Workbook
Name AuroraSize: 'Control Panel >>>'!$B$15
Name CallsPerItem: 'Control Panel >>>'!$B$12
Name ContingencyPct: 'Control Panel >>>'!$B$19
Name DatasetCount: 'Control Panel >>>'!$B$7
Name DeliveriesPerMonth: 'Control Panel >>>'!$B$5
Name EnvMultiplier: 'Control Panel >>>'!$B$14
Name GanttCorrGoLive: Gantt!$AE$4
Name HitlPct: 'Control Panel >>>'!$B$16
Name InputTokensPerCallK: 'Control Panel >>>'!$B$10
Name ItemsPerMonth: 'Control Panel >>>'!$B$22
Name LlmItems: 'Control Panel >>>'!$B$23
Name LlmReachablePct: 'Control Panel >>>'!$B$8
Name ModelSKU: 'Control Panel >>>'!$B$9
Name MonthlyTCO: 'Monthly TCO'!$C$23
Name OutputTokensPerCallK: 'Control Panel >>>'!$B$11
Name PointRate: 'Control Panel >>>'!$B$13
Name ProductsPerDelivery: 'Control Panel >>>'!$B$6
Name RampM1: '12mo Run Cost'!$C$4
Name RampM2: '12mo Run Cost'!$D$4
Name RampM3Plus: '12mo Run Cost'!$E$4
Name Run12mo: '12mo Run Cost'!$O$44
Name SlipWeeks: 'Control Panel >>>'!$B$18
Name StoragePerItemKB: 'Control Panel >>>'!$B$17
Name TotalBuildCost: 'Pod Build'!$J$43
Name TotalBuildPoints: 'Pod Build'!$D$43

Sheet Overview
A1: Overview -- headline TCO + cost waterfall
A2: ="Monthly TCO $"&TEXT(MonthlyTCO,"#,##0.00")&" at Control Panel defaults ("&ModelSKU&", "&TEXT(ItemsPerMonth,"#,##0")&" items/mo). 12-mo run cost $"&TEXT(Run12mo,"#,##0")&". Build: "&TEXT(TotalBuildPoints,"#,##0")&" points x $"&TEXT(PointRate,"#,##0.00")&"/point = $"&TEXT(TotalBuildCost,"#,##0")&"." -> Monthly TCO $1,439.33 at Control Panel defaults (Opus-4.8, 9,890 items/mo). 12-mo run cost $14,846. Build: 95 points x $0.00/point = $0.
A3: HEADLINE
B4: Monthly TCO (at Control Panel defaults) | C4: =MonthlyTCO -> 1439.3256
B5: 12-month run cost total | C5: =Run12mo -> 14846.323
B6: Total build points | C6: =TotalBuildPoints -> 95
B7: Total build cost (Points x PointRate) | C7: =TotalBuildCost -> 0
A9: COST WATERFALL -- MONTHLY TCO BY ZONE
A10: Zone / component | B10: Base (invisible) | C10: Block (visible) | D10: Delta
A11: Zone1 Ingestion | B11: =0 -> 0 | C11: =ABS(D11) -> 8.6509692 | D11: ='Monthly TCO'!$C$5 -> 8.6509692 | E11: =B11+D11 -> 8.6509692
A12: Zone2 ETL/Validation | B12: =E11 -> 8.6509692 | C12: =ABS(D12) -> 0 | D12: ='Monthly TCO'!$C$7 -> 0 | E12: =B12+D12 -> 8.6509692
A13: Zone3 Matching | B13: =E12 -> 8.6509692 | C13: =ABS(D13) -> 887.8094 | D13: ='Monthly TCO'!$C$9 -> 887.8094 | E13: =B13+D13 -> 896.46037
A14: Zone4 Orchestrator+Memory | B14: =E13 -> 896.46037 | C14: =ABS(D14) -> 17.793677 | D14: ='Monthly TCO'!$C$11 -> 17.793677 | E14: =B14+D14 -> 914.25405
A15: Zone4 LLM tokens (LIKELY) | B15: =E14 -> 914.25405 | C15: =ABS(D15) -> 202.745 | D15: ='Monthly TCO'!$C$12 -> 202.745 | E15: =B15+D15 -> 1116.999
A16: Zone4 Dense-arm (opt, 0 default) | B16: =E15 -> 1116.999 | C16: =ABS(D16) -> 0 | D16: ='Monthly TCO'!$C$14 -> 0 | E16: =B16+D16 -> 1116.999
A17: Zone4 Evaluations | B17: =E16 -> 1116.999 | C17: =ABS(D17) -> 0 | D17: ='Monthly TCO'!$C$15 -> 0 | E17: =B17+D17 -> 1116.999
A18: Zone5 Persistence/HITL | B18: =E17 -> 1116.999 | C18: =ABS(D18) -> 18.133318 | D18: ='Monthly TCO'!$C$17 -> 18.133318 | E18: =B18+D18 -> 1135.1324
A19: Platform (always-on) | B19: =E18 -> 1135.1324 | C19: =ABS(D19) -> 116.4551 | D19: ='Monthly TCO'!$C$19 -> 116.4551 | E19: =B19+D19 -> 1251.5875
A21: Cumulative total (should equal Subtotal on Monthly TCO) | E21: =E19 -> 1251.5875
A23: TOP COST DRIVERS
A24: Rank | B24: Zone / component | C24: Monthly cost
A25: 1 | B25: =INDEX($A$11:$A$19,MATCH(C25,$D$11:$D$19,0)) -> Zone3 Matching | C25: =LARGE($D$11:$D$19,1) -> 887.8094
A26: 2 | B26: =INDEX($A$11:$A$19,MATCH(C26,$D$11:$D$19,0)) -> Zone4 LLM tokens (LIKELY) | C26: =LARGE($D$11:$D$19,2) -> 202.745
A27: 3 | B27: =INDEX($A$11:$A$19,MATCH(C27,$D$11:$D$19,0)) -> Platform (always-on) | C27: =LARGE($D$11:$D$19,3) -> 116.4551

Sheet Control Panel >>>
A1: JPMC SCUDO POAP TCO -- Control Panel (all scenarios drive live)
A2: Amber cells are editable inputs -- change a value and every tab, total and chart recalculates live. Status labels: VERIFIED (grounded to source) / INDICATIVE (list price, editable) / DERIVED (formula) / ASSUMPTION (stated basis, editable) / RATE_MISSING (no source rate -- $0 until entered). USD, us-east-1 throughout.
A4: SCENARIO SWITCHES & LOADINGS
A5: DeliveriesPerMonth | B5: 10 | C5: ASSUMPTION | D5: Vendor deliveries per month -> volume model
A6: ProductsPerDelivery | B6: 989 | C6: ASSUMPTION | D6: Products per delivery -> ItemsPerMonth = Deliveries x Products
A7: DatasetCount | B7: 5000 | C7: ASSUMPTION | D7: Catalogue size (CDAO datasets) -> storage lines
A8: LlmReachablePct | B8: 1 | C8: DERIVED | D8: Fraction of items reaching the agent loop. CODE-VERIFIED default: the deployed Strands orchestrator invokes specialist+verifier per product UNCONDITIONALLY (not band-gated) -> 1.0, DERIVED. Lower it to model a band-gated future.
A9: ModelSKU | B9: Opus-4.8 | C9: ASSUMPTION | D9: Bedrock model SKU selection via SKU-gate pattern (vendor fixed = Bedrock)
A10: InputTokensPerCallK | B10: 0.8 | C10: ASSUMPTION | D10: Per-call input tokens (thousands). CODE-VERIFIED LIKELY ~0.69-0.94K (specialist), ~0.38-0.52K (verifier). Client sketch said 50K -> carried as the HIGH scenario row, not the default.
A11: OutputTokensPerCallK | B11: 0.25 | C11: ASSUMPTION | D11: Per-call output tokens (thousands). CODE-VERIFIED LIKELY ~0.21-0.27K.
A12: CallsPerItem | B12: 2 | C12: ASSUMPTION | D12: Bedrock calls per item. CODE-VERIFIED: 2 (mapping specialist + verifier). Dense-arm opus_dense_score is OFF by default (DenseBackend=jaro_winkler); if flipped, it fires per taxonomy node scored -> carried as a separate optional line, default 0.
A13: PointRate | B13: 0 | C13: ASSUMPTION | D13: $ per build point. DEFAULT 0 = RATE_MISSING visible zero (un-costed, not free).
A14: EnvMultiplier | B14: 1 | C14: ASSUMPTION | D14: Non-prod environment multiplier on always-on infra
A15: AuroraSize | B15: 2xlarge | C15: ASSUMPTION | D15: Aurora instance class selector (client sketch says 2xLarge; repo-real default is Serverless v2 db.serverless, a material sizing divergence -- see Assumptions)
A16: HitlPct | B16: 0.15 | C16: ASSUMPTION | D16: Fraction of items routed to HITL review (AppSync traffic)
A17: StoragePerItemKB | B17: 50 | C17: ASSUMPTION | D17: Canonical JSON-LD per product (repo estimate: ~2-4KB actual; 50KB is a conservative client-facing ceiling -- see Assumptions)
A18: SlipWeeks | B18: 0 | C18: ASSUMPTION | D18: Gantt stretch (14-week core, spec 5b with 29->14)
A19: ContingencyPct | B19: 0.15 | C19: ASSUMPTION | D19: Uplift on monthly TCO subtotal
A21: DERIVED VOLUME
A22: Items per month (Deliveries x Products) | B22: =DeliveriesPerMonth*ProductsPerDelivery -> 9890 | C22: DERIVED
A23: LLM-reachable items per month | B23: =ItemsPerMonth*LlmReachablePct -> 9890 | C23: DERIVED
A25: SCOPE NOTES
A26: * LlmReachablePct default 1.0 is CODE-VERIFIED (orchestrator.py:113-151): the deployed Strands orchestrator has no dependency on the confidence-band gate for LLM reachability -- it calls mapping+verifier for every non-RESEARCH product. Lower this to model a future band-gated design.
A27: * InputTokensPerCallK/OutputTokensPerCallK defaults are the CODE-VERIFIED LIKELY scenario (measured prompt-template character counts, llm_call_model.md SS3). The client sketch's 50K in / 1K out is carried as a labelled CLIENT-SKETCH HIGH scenario row on Monthly TCO, not the default.
A28: * PointRate defaults to 0 by design (RATE_MISSING convention): Pod Build shows visible $0 build cost until a real $/point rate is supplied -- this is un-costed, not free.
A29: * AuroraSize offers large/xlarge/2xlarge fixed-instance rates from Rates!, matching the client sketch's 'Aurora db 2xLarge' line. The repo-real deployed config is Aurora Serverless v2 (db.serverless, 0.5-2 ACU) -- a material sizing divergence, see Assumptions.
A30: * StoragePerItemKB defaults to 50KB as a conservative client-facing ceiling. The repo-real measured canonical JSON-LD payload is ~2-4KB per fully-published product (arch_infra_persistence.md SSC.5) -- storage cost at 50KB is a deliberate overstatement, not a repo-measured figure.
A31: * All figures are USD, AWS us-east-1 region only -- no other currency or cloud vendor.

Sheet Rates
A1: Rates -- USD list prices, us-east-1, on-demand (July 2026)
A2: Every figure on this tab is an editable input. All rates VERIFIED from AWS Price List Bulk API / aws.amazon.com/*/pricing pages, us-east-1, as cited per row. RATE_MISSING lines are $0 until a real rate is supplied. USD only.
A4: Rate | B4: Unit | C4: Value (USD) | D4: Status | E4: Source URL | F4: Notes / As-of
A5: AMAZON AURORA POSTGRESQL
A6: db.r6g.2xlarge Single-AZ instance (Standard) | B6: USD per hour | C6: 1.038 | D6: VERIFIED | E6: https://pricing.us-east-1.amazonaws.com/offers/v1.0/aws/AmazonRDS/current/us-east-1/index.json | F6: AWS Price List Bulk API (AmazonRDS), sku attrs databaseEngine=Aurora PostgreSQL, instanceType=db.r6g.2xlarge, deploymentOption=Single-AZ, usagetype=InstanceUsage:db.r6g.2xl. As of publicationDate 2026-07-21T17:58:18Z. Matches client sketch's 'Aurora db 2xLarge'.
A7: db.r6g.2xlarge Single-AZ instance (I/O-Optimized) | B7: USD per hour | C7: 1.349 | D7: VERIFIED | E7: https://pricing.us-east-1.amazonaws.com/offers/v1.0/aws/AmazonRDS/current/us-east-1/index.json | F7: Same source/date as above; usagetype=InstanceUsageIOOptimized:db.r6g.2xl. I/O-Optimized carries no per-I/O charge (see storage row) but a higher instance rate.
A8: db.r6g.xlarge Single-AZ instance (Standard) — cheaper alternate | B8: USD per hour | C8: 0.519 | D8: VERIFIED | E8: https://pricing.us-east-1.amazonaws.com/offers/v1.0/aws/AmazonRDS/current/us-east-1/index.json | F8: usagetype=InstanceUsage:db.r6g.xl. As of 2026-07-21.
A9: db.r6g.xlarge Single-AZ instance (I/O-Optimized) | B9: USD per hour | C9: 0.675 | D9: VERIFIED | E9: https://pricing.us-east-1.amazonaws.com/offers/v1.0/aws/AmazonRDS/current/us-east-1/index.json | F9: usagetype=InstanceUsageIOOptimized:db.r6g.xl.
A10: db.r6g.large Single-AZ instance (Standard) — cheaper alternate | B10: USD per hour | C10: 0.26 | D10: VERIFIED | E10: https://pricing.us-east-1.amazonaws.com/offers/v1.0/aws/AmazonRDS/current/us-east-1/index.json | F10: usagetype=InstanceUsage:db.r6g.large.
A11: db.r6g.large Single-AZ instance (I/O-Optimized) | B11: USD per hour | C11: 0.338 | D11: VERIFIED | E11: https://pricing.us-east-1.amazonaws.com/offers/v1.0/aws/AmazonRDS/current/us-east-1/index.json | F11: usagetype=InstanceUsageIOOptimized:db.r6g.large.
A12: AMAZON AURORA SERVERLESS V2 (POSTGRESQL)
A13: Aurora Capacity Unit (Standard config) | B13: USD per ACU-hour | C13: 0.12 | D13: VERIFIED | E13: https://pricing.us-east-1.amazonaws.com/offers/v1.0/aws/AmazonRDS/current/us-east-1/index.json | F13: usagetype=Aurora:ServerlessV2Usage.
A14: Aurora Capacity Unit (I/O-Optimized config) | B14: USD per ACU-hour | C14: 0.16 | D14: VERIFIED | E14: https://pricing.us-east-1.amazonaws.com/offers/v1.0/aws/AmazonRDS/current/us-east-1/index.json | F14: usagetype=Aurora:ServerlessV2IOOptimizedUsage.
A15: AMAZON AURORA POSTGRESQL
A16: Consumed storage (Standard) | B16: USD per GB-month | C16: 0.1 | D16: VERIFIED | E16: https://pricing.us-east-1.amazonaws.com/offers/v1.0/aws/AmazonRDS/current/us-east-1/index.json | F16: usagetype=Aurora:StorageUsage. Standard config also bills I/O separately (next row); I/O-Optimized rolls I/O into a higher $/GB-mo rate with zero per-I/O charge.
A17: Consumed storage (I/O-Optimized) | B17: USD per GB-month | C17: 0.225 | D17: VERIFIED | E17: https://pricing.us-east-1.amazonaws.com/offers/v1.0/aws/AmazonRDS/current/us-east-1/index.json | F17: usagetype=Aurora:IO-OptimizedStorageUsage. I/O-Optimized has $0 per-I/O charge — all read/write I/O cost is folded into this higher storage rate vs. the 0.10 Standard rate.
A18: I/O requests (Standard config only) | B18: USD per 1,000,000 I/Os | C18: 0.2 | D18: VERIFIED | E18: https://pricing.us-east-1.amazonaws.com/offers/v1.0/aws/AmazonRDS/current/us-east-1/index.json | F18: usagetype=Aurora:StorageIOUsage ($0.0000002/IO). Only billed under Standard storage config; I/O-Optimized has no separate I/O charge (folded into the 0.225 GB-mo storage rate above).
A19: AMAZON OPENSEARCH SERVICE
A20: r7g.large.search on-demand instance | B20: USD per hour | C20: 0.178 | D20: VERIFIED | E20: https://pricing.us-east-1.amazonaws.com/offers/v1.0/aws/AmazonES/current/us-east-1/index.json | F20: AWS Price List Bulk API (AmazonES), instanceType=r7g.large.search, usagetype=ESInstance:r7g.large. As of publicationDate 2026-07-09T09:08:58Z.
A21: m7g.large.search on-demand instance | B21: USD per hour | C21: 0.135 | D21: VERIFIED | E21: https://pricing.us-east-1.amazonaws.com/offers/v1.0/aws/AmazonES/current/us-east-1/index.json | F21: instanceType=m7g.large.search, usagetype=ESInstance:m7g.large.
A22: t3.small.search on-demand instance (dev/test) | B22: USD per hour | C22: 0.036 | D22: VERIFIED | E22: https://pricing.us-east-1.amazonaws.com/offers/v1.0/aws/AmazonES/current/us-east-1/index.json | F22: instanceType=t3.small.search, usagetype=ESInstance:t3.small.
A23: EBS gp3 provisioned storage | B23: USD per GB-month | C23: 0.122 | D23: VERIFIED | E23: https://pricing.us-east-1.amazonaws.com/offers/v1.0/aws/AmazonES/current/us-east-1/index.json | F23: usagetype=ES:GP3-Storage. gp3 also has separate optional provisioned-IOPS ($0.008/PIOPS-mo) and provisioned-throughput ($0.064/MiBps-mo) meters not requested in the brief.
A24: AMAZON OPENSEARCH SERVERLESS
A25: Indexing OCU / Search OCU (compute) | B25: USD per OCU-hour | C25: 0.24 | D25: VERIFIED | E25: https://pricing.us-east-1.amazonaws.com/offers/v1.0/aws/AmazonES/current/us-east-1/index.json | F25: usagetype=USE1-IndexingOCU and USE1-SearchOCU, both $0.24/OCU-hr identically. As of 2026-07-09.
A26: Minimum billed OCUs — production (redundancy) vs dev/test | B26: OCU count (not USD) | C26: 0 | D26: VERIFIED | E26: https://docs.aws.amazon.com/opensearch-service/latest/developerguide/serverless-scaling.html | F26: CORRECTION to brief's framing: current AWS docs (fetched 2026-07-22) state the minimum is 2 OCUs total with redundancy ON (1 OCU=[0.5x2] indexing + 1 OCU=[0.5x2] search, for HA) vs 1 OCU total with redundancy OFF/dev-test (0.5 indexing + 0.5 search) — NOT '4-OCU vs 2-OCU' as the brief's note suggested. At $0.24/OCU-hr, production-minimum ~2 OCU x $0.24 x 730hr = ~$350/mo; dev-minimum ~1 OCU x $0.24 x 730hr = ~$175/mo. Flagging this discrepancy rather than fabricating a 4-OCU figure to match the brief's wording.
A27: AMAZON DYNAMODB (ON-DEMAND CAPACITY)
A28: Write request units | B28: USD per 1,000,000 WRU | C28: 0.625 | D28: VERIFIED | E28: https://pricing.us-east-1.amazonaws.com/offers/v1.0/aws/AmazonDynamoDB/current/us-east-1/index.json | F28: usagetype=WriteRequestUnits, group=DDB-WriteUnits, description '$0.625 per million write request units (N. Virginia)'. Standard table class. As of publicationDate 2026-07-22T00:38:27Z.
A29: Read request units | B29: USD per 1,000,000 RRU | C29: 0.125 | D29: VERIFIED | E29: https://pricing.us-east-1.amazonaws.com/offers/v1.0/aws/AmazonDynamoDB/current/us-east-1/index.json | F29: usagetype=ReadRequestUnits, group=DDB-ReadUnits, description '$0.125 per million read request units (N. Virginia)'. Standard table class.
A30: AMAZON DYNAMODB
A31: Storage (Standard table class, beyond 25GB free tier) | B31: USD per GB-month | C31: 0.25 | D31: VERIFIED | E31: https://pricing.us-east-1.amazonaws.com/offers/v1.0/aws/AmazonDynamoDB/current/us-east-1/index.json | F31: usagetype=TimedStorage-ByteHrs, priced tier beyond first 25 free GB-months (first 25 GB-mo is $0/GB). Standard-IA table class is cheaper at $0.10/GB-mo if applicable.
A32: AMAZON NEPTUNE
A33: db.r6g.large instance (Standard) | B33: USD per hour | C33: 0.3287 | D33: VERIFIED | E33: https://pricing.us-east-1.amazonaws.com/offers/v1.0/aws/AmazonNeptune/current/us-east-1/index.json | F33: AWS Price List Bulk API (AmazonNeptune), instanceType=db.r6g.large, usagetype=InstanceUsage:db.r6g.large. Publication date in file is stale (2026-03-13) — cross-check against live console before finalizing budget; no newer bulk-API snapshot was available at fetch time so this is the latest published rate, not a guess.
A34: db.r6g.large instance (I/O-Optimized) | B34: USD per hour | C34: 0.443 | D34: VERIFIED | E34: https://pricing.us-east-1.amazonaws.com/offers/v1.0/aws/AmazonNeptune/current/us-east-1/index.json | F34: usagetype=InstanceUsageIOOptimized:db.r6g.large. Same file caveat as above (publicationDate 2026-03-13T14:07:01Z).
A35: Storage (Standard) | B35: USD per GB-month | C35: 0.1 | D35: VERIFIED | E35: https://pricing.us-east-1.amazonaws.com/offers/v1.0/aws/AmazonNeptune/current/us-east-1/index.json | F35: usagetype=StorageUsage. I/O-Optimized storage is $0.225/GB-mo (usagetype=IO-OptimizedStorageUsage), mirroring the Aurora pattern.
A36: I/O requests (Standard config only) | B36: USD per 1,000,000 I/Os | C36: 0.2 | D36: VERIFIED | E36: https://pricing.us-east-1.amazonaws.com/offers/v1.0/aws/AmazonNeptune/current/us-east-1/index.json | F36: usagetype=StorageIOUsage. Context per brief: repo ships Neptune CFN templates but the live PoC runs FalkorDB on ECS instead — Neptune priced here for comparison, not as the deployed graph store.
A37: AWS FARGATE (X86/LINUX, ON ECS)
A38: vCPU-hour | B38: USD per vCPU-hour | C38: 0.04048 | D38: VERIFIED | E38: https://pricing.us-east-1.amazonaws.com/offers/v1.0/aws/AmazonECS/current/us-east-1/index.json | F38: usagetype=USE1-Fargate-vCPU-Hours:perCPU. As of publicationDate 2026-07-07T16:06:51Z. ARM/Graviton Fargate is cheaper at $0.03238/vCPU-hr (usagetype=USE1-Fargate-ARM-vCPU-Hours:perCPU).
A39: GB-hour (memory) | B39: USD per GB-hour | C39: 0.004445 | D39: VERIFIED | E39: https://pricing.us-east-1.amazonaws.com/offers/v1.0/aws/AmazonECS/current/us-east-1/index.json | F39: usagetype=USE1-Fargate-GB-Hours. ARM/Graviton is cheaper at $0.00356/GB-hr (usagetype=USE1-Fargate-ARM-GB-Hours).
A40: AWS FARGATE
A41: Monthly example: 0.25 vCPU / 0.5 GB, always-on (730 hr/mo) | B41: USD per month | C41: 9.01 | D41: VERIFIED | E41: https://pricing.us-east-1.amazonaws.com/offers/v1.0/aws/AmazonECS/current/us-east-1/index.json | F41: Derived calc: (0.25 vCPU x $0.04048/hr + 0.5 GB x $0.004445/hr) x 730 hr = $9.01/mo. x86/Linux rates; excludes ephemeral storage beyond the free 20GB and any data transfer.
...

Sheet Pod Build
A1: Pod Build -- client table shape + repo-real extras
A2: ="Points x PointRate (currently $"&TEXT(PointRate,"#,##0.00")&"/point) -- PointRate defaults to 0 (RATE_MISSING convention): visible zero, un-costed not free until a real rate is supplied." -> Points x PointRate (currently $0.00/point) -- PointRate defaults to 0 (RATE_MISSING convention): visible zero, un-costed not free until a real rate is supplied.
A3: Pod | B3: Short Title | C3: AWS Components | D3: Points | E3: Run freq per mo | F3: Est data vol GB | G3: Input tokens K | H3: Output tokens K | I3: Cost estimate $ monthly | J3: Build cost (Points x PointRate) | K3: Status | L3: Basis / source | M3: Dense-arm mult. (0=off)
A4: A | B4: API GW entry + routing | C4: API Gateway (HttpApi) | D4: 2 | E4: =ItemsPerMonth -> 9890 | F4: - | G4: - | H4: - | I4: =ItemsPerMonth*Rates!$C$79/1000000 -> 0.034615 | J4: =D4*PointRate -> 0 | K4: ASSUMPTION | L4: Points: relative sizing, no client estimate supplied. Cost: ItemsPerMonth requests through the /run route, ApiGatewayRequest rate. template.yaml:589-599.
A5: A | B5: Lambda authorizer | C5: Lambda (auth check) | D5: 1 | E5: - | F5: - | G5: - | H5: - | I5: =ItemsPerMonth*0 -> 0 | J5: =D5*PointRate -> 0 | K5: ASSUMPTION | L5: No JWT Lambda authorizer exists in the repo today (auth is an API-key header) -- arch_infra_persistence.md D.1. RATE_MISSING: $0, un-costed, not free, until this component is actually built.
A6: A | B6: Ingestion Coordinator (ETL worker) | C6: Lambda EtlFn, 3008MB, SQS-triggered | D6: 3 | E6: =ItemsPerMonth -> 9890 | F6: - | G6: - | H6: - | I6: =ItemsPerMonth*2.9375*2*Rates!$C$81+ItemsPerMonth*Rates!$C$82/1000000 -> 0.97037577 | J6: =D6*PointRate -> 0 | K6: DERIVED | L6: template.yaml:16-25 EtlFn 3008MB default memory, SQS BatchSize 5. Duration ASSUMPTION (~2s/product, no repo timing evidence); GB-second + per-request Lambda rates.
A7: A | B7: Sanity Check (validate/quarantine) | C7: In-process in EtlFn -- no separate Lambda | D7: 1 | E7: - | F7: - | G7: - | H7: - | I7: =ItemsPerMonth*0 -> 0 | J7: =D7*PointRate -> 0 | K7: DERIVED | L7: etl_handler.py _process_object/_quarantine run inside EtlFn -- no incremental compute cost beyond the Ingestion Coordinator line above.
A8: A | B8: CloudWatch (logs + metrics) | C8: CloudWatch log groups, EMF metrics, dashboard | D8: 1 | E8: =ItemsPerMonth -> 9890 | F8: =ItemsPerMonth*2/1000000 -> 0.01978 | G8: - | H8: - | I8: =(ItemsPerMonth*2/1000000)*(Rates!$C$94+Rates!$C$95)+15*Rates!$C$96+1*Rates!$C$97 -> 7.5104834 | J8: =D8*PointRate -> 0 | K8: ASSUMPTION | L8: ~2KB structured log per product ASSUMPTION; 15 custom EMF metrics per MEMORY note; 1 dashboard. arch_infra_persistence.md A.8.
A9: A | B9: S3 raw landing | C9: S3 RawFeedBucket | D9: 1 | E9: =ItemsPerMonth -> 9890 | F9: =ItemsPerMonth*StoragePerItemKB/1000000 -> 0.4945 | G9: - | H9: - | I9: =ItemsPerMonth*1*Rates!$C$85/1000+ItemsPerMonth*0*Rates!$C$86/1000+ItemsPerMonth*StoragePerItemKB/1000000*Rates!$C$84 -> 0.0608235 | J9: =D9*PointRate -> 0 | K9: DERIVED | L9: template.yaml:176-198 RawFeedBucket, EventBridge-notification-enabled. 1 PUT/vendor object at ingest, storage sized via StoragePerItemKB.
A10: A | B10: EventBridge Scheduler (poller) | C10: EventBridge Scheduler, cron twice-monthly | D10: 1 | E10: 2 | F10: - | G10: - | H10: - | I10: =2*Rates!$C$92/1000000 -> 2e-06 | J10: =D10*PointRate -> 0 | K10: VERIFIED | L10: PollerFn cron(0 6 1,15 * ? *) -- twice-monthly, not per-product. arch_infra_persistence.md A.1/A.3.
A11: A | B11: EventBridge ObjectCreated rule | C11: EventBridge rule, S3->SQS | D11: 1 | E11: =ItemsPerMonth -> 9890 | F11: - | G11: - | H11: - | I11: =ItemsPerMonth*1*Rates!$C$90/1000000 -> 0.00989 | J11: =D11*PointRate -> 0 | K11: VERIFIED | L11: RawFeedIngressRule on default bus, S3 Object Created -> EtlQueue. arch_infra_persistence.md A.3.
A12: A | B12: SQS (EtlQueue + DLQ) | C12: SQS standard queue + DLQ | D12: 1 | E12: =ItemsPerMonth -> 9890 | F12: - | G12: - | H12: - | I12: =ItemsPerMonth*1*Rates!$C$88/1000000 -> 0.003956 | J12: =D12*PointRate -> 0 | K12: VERIFIED | L12: EtlQueue BatchSize 5, DLQ after 3 receives. template.yaml A.2.
A13: A | B13: ETL worker VPC egress (NAT) | C13: NAT Gateway (no-VPC EtlFn needs internet egress) | D13: 1 | E13: - | F13: - | G13: - | H13: - | I13: =ItemsPerMonth*0 -> 0 | J13: =D13*PointRate -> 0 | K13: DERIVED | L13: EtlFn explicitly has NO VPC (template.yaml:488-491); NAT cost is carried once as a shared always-on line under Pod E Platform, not duplicated here -- see Pod E.
A14: A | B14: S3 canonical sink | C14: S3 CleanCanonicalBucket | D14: 1 | E14: =ItemsPerMonth -> 9890 | F14: =ItemsPerMonth*StoragePerItemKB/1000000 -> 0.4945 | G14: - | H14: - | I14: =ItemsPerMonth*1*Rates!$C$85/1000+ItemsPerMonth*0*Rates!$C$86/1000+ItemsPerMonth*StoragePerItemKB/1000000*Rates!$C$84 -> 0.0608235 | J14: =D14*PointRate -> 0 | K14: DERIVED | L14: CleanCanonicalBucket, written by etl_handler.py pass path. 1 PUT/product.
A15: A | B15: S3 quarantine | C15: S3 QuarantineBucket | D15: 1 | E15: =ItemsPerMonth -> 9890 | F15: - | G15: - | H15: - | I15: =ItemsPerMonth*0*Rates!$C$85/1000+ItemsPerMonth*0*Rates!$C$86/1000 -> 0 | J15: =D15*PointRate -> 0 | K15: ASSUMPTION | L15: QuarantineBucket, mutually exclusive with canonical PUT (bad-file path only) -- modelled at $0 incremental (rare-path, no repo-measured quarantine rate).
A16: B | B16: AIA Matching Engine gate A (scope) | C16: In-process, matching.py | D16: 2 | E16: - | F16: - | G16: - | H16: - | I16: =ItemsPerMonth*0 -> 0 | J16: =D16*PointRate -> 0 | K16: DERIVED | L16: Deterministic Python gate, no separate compute -- folded into the matching Lambda compute already priced on the Strands Orchestrator line (Pod C). ZONES.md Zone 3.
A17: B | B17: AIA Matching Engine gate B (precedent) | C17: In-process, aurora_memory.py CONSULT | D17: 2 | E17: - | F17: - | G17: - | H17: - | I17: =ItemsPerMonth*0 -> 0 | J17: =D17*PointRate -> 0 | K17: RATE_MISSING | L17: 1 Aurora RDS Data API ExecuteStatement per item for precedent lookup (arch_infra_persistence.md C.4 roll-up), but rates.json has no per-request RDS Data API meter -- the underlying Aurora instance-hour cost is already priced on the Aurora 2xlarge line below; this row's incremental per-call charge is $0, un-costed not free, until a Data API request rate is sourced.
A18: B | B18: AIA Matching Engine gate C (hybrid retrieval) | C18: FalkorDB on ECS (retrieval store) | D18: 3 | E18: Always-on (shared, see Pod E) | F18: - | G18: - | H18: - | I18: =ItemsPerMonth*0 -> 0 | J18: =D18*PointRate -> 0 | K18: DERIVED | L18: FalkorDB on Fargate is the live retrieval store (both deploy paths) -- always-on ECS task cost carried once under Pod E Platform, not duplicated per-pod. arch_infra_persistence.md A.8.
A19: B | B19: Titan Embeddings (indexing/write path) | C19: Bedrock Titan Text Embeddings V2 | D19: 2 | E19: =LlmItems -> 9890 | F19: - | G19: 0.5 | H19: 0 | I19: =LlmItems*0.5*Rates!$C$139/1000 -> 0.0989 | J19: =D19*PointRate -> 0 | K19: VERIFIED | L19: Titan IS called from projection_handler.py:483 on the write/index path only (not retrieval, which is parked). ~0.5K tokens/item ASSUMPTION for a short product description embed.
A20: B | B20: OpenSearch fuzzy+kNN | C20: OpenSearch Service r7g.large.search + gp3 storage | D20: 4 | E20: Always-on | F20: =DatasetCount*StoragePerItemKB/1000000 -> 0.25 | G20: - | H20: - | I20: =730*EnvMultiplier*Rates!$C$20+DatasetCount*StoragePerItemKB/1000000*Rates!$C$59 -> 129.9705 | J20: =D20*PointRate -> 0 | K20: DERIVED | L20: Template-real domain; write path real (_index_opensearch), matching read path today is a Jaro-Winkler/FalkorDB seam not OpenSearch kNN. Priced at the always-on domain cost the client's list implies. arch_infra_persistence.md A.7/A.8.
A21: B | B21: Aurora 2xlarge (system of record) | C21: Aurora PostgreSQL, AuroraSize selector | D21: 5 | E21: Always-on | F21: - | G21: - | H21: - | I21: =730*EnvMultiplier*IF(AuroraSize="large",Rates!$C$10,IF(AuroraSize="xlarge",Rates!$C$8,Rates!$C$6)) -> 757.74 | J21: =D21*PointRate -> 0 | K21: DERIVED | L21: Client sketch says 'Aurora db 2xLarge'; repo-real deployed shape is Aurora Serverless v2 (db.serverless) -- material divergence, see Assumptions. This line prices the client's fixed-instance-class ask via the AuroraSize selector.
A22: C | B22: Strands Orchestrator Opus 4.8 | C22: Lambda ScudoFn (3008MB) + Bedrock routing | D22: 5 | E22: =ItemsPerMonth -> 9890 | F22: - | G22: - | H22: - | I22: =ItemsPerMonth*2.9375*1*Rates!$C$81+ItemsPerMonth*Rates!$C$82/1000000 -> 0.48617689 | J22: =D22*PointRate -> 0 | K22: VERIFIED | L22: ScudoFn 3008MB default, no LLM call in Orchestrator.route() itself (deterministic Python). orchestrator.py:102-110; llm_call_model.md SS1.
A23: C | B23: AgentCore Memory (short-term events) | C23: Bedrock AgentCore Memory meter (bespoke store) | D23: 3 | E23: =LlmItems -> 9890 | F23: - | G23: - | H23: - | I23: =LlmItems*2*Rates!$C$145/1000 -> 4.945 | J23: =D23*PointRate -> 0 | K23: VERIFIED | L23: Client wants this priced; repo-real substrate is aurora_memory.py (bespoke), not the managed AgentCore Memory service (arch_infra_persistence.md D.1). Rate from Bedrock AgentCore Memory short-term-events meter, applied notionally as the client-facing unit-cost analog.
A24: C | B24: AgentCore Memory (long-term records) | C24: Bedrock AgentCore Memory, built-in strategies | D24: 2 | E24: =LlmItems -> 9890 | F24: - | G24: - | H24: - | I24: =LlmItems*1*Rates!$C$146/1000 -> 7.4175 | J24: =D24*PointRate -> 0 | K24: ASSUMPTION | L24: 1 long-term record/item ASSUMPTION (no repo-measured record count); rate VERIFIED from rates.json.
A25: C | B25: AgentCore Memory (long-term retrieval) | C25: Bedrock AgentCore Memory retrieval meter | D25: 2 | E25: =LlmItems -> 9890 | F25: - | G25: - | H25: - | I25: =LlmItems*1*Rates!$C$148/1000 -> 4.945 | J25: =D25*PointRate -> 0 | K25: ASSUMPTION | L25: 1 retrieval/item ASSUMPTION; rate VERIFIED from rates.json.
A26: C | B26: Specialist agent (mapping) | C26: Bedrock InvokeModel, ModelSKU-gated | D26: 4 | E26: =LlmItems -> 9890 | F26: - | G26: =InputTokensPerCallK -> 0.8 | H26: =OutputTokensPerCallK -> 0.25 | I26: =LlmItems*1*(InputTokensPerCallK/1000*IF(ModelSKU="Opus-4.8",Rates!$C$121,IF(ModelSKU="Sonnet-5",Rates!$C$127,Rates!$C$133))+OutputTokensPerCallK/1000*IF(ModelSKU="Opus-4.8",Rates!$C$122,IF(ModelSKU="Sonnet-5",Rates!$C$128,Rates!$C$134))) -> 101.3725 | J26: =D26*PointRate -> 0 | K26: VERIFIED | L26: 1 InvokeModel call/product via _call_mapping (orchestrator.py:191-203). SKU-gated token cost -- see Monthly TCO for the full CODE-VERIFIED LIKELY / CLIENT-SKETCH HIGH scenario rows.
A27: C | B27: Verifier agent 10-dim | C27: Bedrock InvokeModel, ModelSKU-gated | D27: 4 | E27: =LlmItems -> 9890 | F27: - | G27: =InputTokensPerCallK -> 0.8 | H27: =OutputTokensPerCallK -> 0.25 | I27: =LlmItems*1*(InputTokensPerCallK/1000*IF(ModelSKU="Opus-4.8",Rates!$C$121,IF(ModelSKU="Sonnet-5",Rates!$C$127,Rates!$C$133))+OutputTokensPerCallK/1000*IF(ModelSKU="Opus-4.8",Rates!$C$122,IF(ModelSKU="Sonnet-5",Rates!$C$128,Rates!$C$134))) -> 101.3725 | J27: =D27*PointRate -> 0 | K27: VERIFIED | L27: 1 InvokeModel call/product via _call_verifier (orchestrator.py:237-261), 10-dim rubric, VerifierReport min_length=10/max_length=10. schemas.py:219-247.
A28: C | B28: Dense-arm optional (opus_dense per node) | C28: Bedrock InvokeModel, opt-in, default OFF | D28: 3 | E28: =ItemsPerMonth*$M$28 -> 0 | F28: - | G28: 0.5 | H28: 0.08 | I28: =ItemsPerMonth*$M$28*(0.5/1000*IF(ModelSKU="Opus-4.8",Rates!$C$121,IF(ModelSKU="Sonnet-5",Rates!$C$127,Rates!$C$133))+0.08/1000*IF(ModelSKU="Opus-4.8",Rates!$C$122,IF(ModelSKU="Sonnet-5",Rates!$C$128,Rates!$C$134))) -> 0 | J28: =D28*PointRate -> 0 | K28: DERIVED | L28: Only fires if SCUDO_DENSE_BACKEND=opus (default jaro_winkler, infra/scudo-poc-app.yaml:76-79) -- OFF by default, amber multiplier default 0. When on: N calls/product, N=taxonomy nodes scored (14 in the demo fixture). llm_call_model.md SS1/SS3. | M28: 0
A29: C | B29: Bedrock Evaluations (judge) | C29: LLM-as-judge, billed as judge model's own tokens | D29: 2 | E29: - | F29: - | G29: - | H29: - | I29: =ItemsPerMonth*0 -> 0 | J29: =D29*PointRate -> 0 | K29: ASSUMPTION | L29: No separate meter for LLM-as-judge (rates.json: billed as judge model's standard tokens). Repo has no real Bedrock Evaluations API call anywhere -- bespoke offline harness instead (arch_infra_persistence.md D.1). $0 incremental line, human-eval meter available in Rates if wired later.
A30: D | B30: JAPI Persist outbox writer | C30: Aurora ExecuteStatement (RDS Data API) | D30: 5 | E30: - | F30: - | G30: - | H30: - | I30: =ItemsPerMonth*0 -> 0 | J30: =D30*PointRate -> 0 | K30: RATE_MISSING | L30: ~10 ExecuteStatement calls/fully-published product (outbox insert + projection rows) -- VERIFIED call count, arch_infra_persistence.md SSC, persistence-ops-per-product roll-up. No per-request RDS Data API rate in rates.json, so the incremental per-call charge is $0 (un-costed not free) until sourced; the Aurora instance-hour cost itself is priced separately on the Aurora 2xlarge line.
A31: D | B31: Outbox sweep (EventBridge Schedule) | C31: rate(5 min) Scheduler -> Lambda sweep | D31: 3 | E31: 8928 | F31: - | G31: - | H31: - | I31: =8928*Rates!$C$92/1000000 -> 0.008928 | J31: =D31*PointRate -> 0 | K31: VERIFIED | L31: rate(5 min) = 12/hr * 24 * mean(30.4 days) ~= 8928 invokes/mo, flat regardless of volume. projection_handler.py sweep_outbox; infra/HANDOVER_5zone_alignment.md.
A32: D | B32: HITL AppSync API | C32: AppSync GraphQL ops + notifications | D32: 4 | E32: =ItemsPerMonth*HitlPct -> 1483.5 | F32: - | G32: - | H32: - | I32: =ItemsPerMonth*HitlPct*6*Rates!$C$117/1000000 -> 0.035604 | J32: =D32*PointRate -> 0 | K32: ASSUMPTION | L32: 6 GraphQL ops/HITL item (list+get+mutate+subscribe-notify) is an ASSUMPTION -- no repo-measured op count; HitlPct selector gates volume. rate VERIFIED from rates.json.
A33: D | B33: HITL review ECS task (reviewer console) | C33: Fargate, always-on shared task | D33: 4 | E33: Always-on | F33: - | G33: - | H33: - | I33: =730*EnvMultiplier*(0.5*Rates!$C$38+1*Rates!$C$39) -> 18.02005 | J33: =D33*PointRate -> 0 | K33: DERIVED | L33: Shared with Pod E platform ECS allocation -- this row shows the HITL-attributable slice only, full task priced once under Pod E to avoid double count.
A34: D | B34: S3 projection sink + CloudFront invalidation | C34: S3 PUT/GET + CloudFront requests | D34: 2 | E34: =ItemsPerMonth -> 9890 | F34: =ItemsPerMonth*StoragePerItemKB/1000000 -> 0.4945 | G34: - | H34: - | I34: =ItemsPerMonth*1*Rates!$C$85/1000+ItemsPerMonth*2*Rates!$C$86/1000+ItemsPerMonth*StoragePerItemKB/1000000*Rates!$C$84 -> 0.0687355 | J34: =D34*PointRate -> 0 | K34: ASSUMPTION | L34: 1 PUT (projection write) + 2 GET (dashboard reads)/item ASSUMPTION.
A35: E | B35: FalkorDB on ECS (retrieval store) | C35: Fargate task, always-on, shared | D35: 5 | E35: Always-on | F35: - | G35: - | H35: - | I35: =730*EnvMultiplier*(1*Rates!$C$38+2*Rates!$C$39) -> 36.0401 | J35: =D35*PointRate -> 0 | K35: VERIFIED | L35: Actual live hybrid-retrieval substrate (Neptune/OpenSearch-kNN are dormant seams). 1 vCPU / 2GB always-on Fargate task. ZONES.md Zone3; ua-dogfood-scudo memory.
A36: E | B36: CloudFront distribution | C36: Requests + data transfer out, PoC demo | D36: 4 | E36: 50000 | F36: 10 | G36: - | H36: - | I36: =50000*Rates!$C$115/10000+10*Rates!$C$114 -> 0.9 | J36: =D36*PointRate -> 0 | K36: ASSUMPTION | L36: 50k requests / 10GB out per month is an ASSUMPTION sized for a PoC-scale demo, not production traffic -- see Assumptions sheet.
A37: E | B37: ALB (console + API ingress) | C37: Hourly + LCU-hours, always-on | D37: 3 | E37: Always-on | F37: - | G37: - | H37: - | I37: =730*EnvMultiplier*Rates!$C$102+730*EnvMultiplier*1*Rates!$C$103 -> 22.265 | J37: =D37*PointRate -> 0 | K37: VERIFIED | L37: 1 ALB, always-on hourly charge + nominal LCU-hours. infra/scudo-poc-*.yaml.
A38: E | B38: NAT Gateway (VPC egress) | C38: Hourly + per-GB processed, always-on | D38: 3 | E38: Always-on | F38: 20 | G38: - | H38: - | I38: =730*EnvMultiplier*Rates!$C$105+20*Rates!$C$106 -> 33.75 | J38: =D38*PointRate -> 0 | K38: ASSUMPTION | L38: 20GB/mo egress ASSUMPTION (ETL worker + Lambda-in-VPC egress); this is the priced line that Pod A's nat_share and Pod B's aurora_ops VPC path reference.
A39: E | B39: Secrets Manager (DB + API creds) | C39: Per-secret + API-call meter | D39: 1 | E39: Always-on | F39: - | G39: - | H39: - | I39: =4*Rates!$C$108 -> 1.6 | J39: =D39*PointRate -> 0 | K39: VERIFIED | L39: 4 secrets (CONSOLE_DB_PASSWORD, Bedrock/API keys, MFT gateway cred, JWT signing key).
A40: E | B40: VPC Interface Endpoints | C40: Per-endpoint-hour + per-GB, always-on | D40: 2 | E40: Always-on | F40: - | G40: - | H40: - | I40: =3*730*EnvMultiplier*Rates!$C$111 -> 21.9 | J40: =D40*PointRate -> 0 | K40: ASSUMPTION | L40: 3 endpoints ASSUMPTION (Secrets Manager, Bedrock, S3-gateway-equivalent) -- no repo-measured endpoint count.
...

Sheet Monthly TCO
A1: Monthly TCO -- grouped by zone, formula-linked to Pod Build
A2: ="Contingency uplift "&TEXT(ContingencyPct,"0.0%")&" applied to the subtotal below. Three scenario rows show the LLM token cost under different framings -- only the CODE-VERIFIED LIKELY row (Control Panel defaults) feeds the total." -> Contingency uplift 15.0% applied to the subtotal below. Three scenario rows show the LLM token cost under different framings -- only the CODE-VERIFIED LIKELY row (Control Panel defaults) feeds the total.
A3: Zone | B3: Component | C3: Monthly cost formula | D3: Status | E3: Basis / source
A4: ZONE 1 -- INGESTION
A5: Zone1 | B5: API GW + Lambda ETL + S3 + SQS + EventBridge (Pod A total) | C5: ='Pod Build'!$I$4+'Pod Build'!$I$5+'Pod Build'!$I$6+'Pod Build'!$I$7+'Pod Build'!$I$8+'Pod Build'!$I$9+'Pod Build'!$I$10+'Pod Build'!$I$11+'Pod Build'!$I$12+'Pod Build'!$I$13+'Pod Build'!$I$14+'Pod Build'!$I$15 -> 8.6509692 | D5: DERIVED | E5: Cross-links to Pod Build Pod A rows (4-15); avoids re-deriving the same formulas twice.
A6: ZONE 2 -- ETL / VALIDATION
A7: Zone2 | B7: Sanity check + quarantine (folded into Pod A compute) | C7: =0 -> 0 | D7: DERIVED | E7: No incremental Zone2 compute beyond Zone1's Ingestion Coordinator Lambda -- etl_handler.py validate/quarantine run in-process.
A8: ZONE 3 -- MATCHING
A9: Zone3 | B9: Matching Engine + Titan + OpenSearch + Aurora (Pod B total) | C9: ='Pod Build'!$I$16+'Pod Build'!$I$17+'Pod Build'!$I$18+'Pod Build'!$I$19+'Pod Build'!$I$20+'Pod Build'!$I$21 -> 887.8094 | D9: DERIVED | E9: Cross-links to Pod Build Pod B rows (16-21).
A10: ZONE 4 -- AGENTIC
A11: Zone4 | B11: Strands Orchestrator + AgentCore Memory (Pod C infra rows) | C11: ='Pod Build'!$I$22+'Pod Build'!$I$23+'Pod Build'!$I$24+'Pod Build'!$I$25 -> 17.793677 | D11: DERIVED | E11: Cross-links to Pod Build Pod C rows 22-25 (orchestrator Lambda + AgentCore Memory short-term/long-term/retrieval).
A12: Zone4 | B12: LLM tokens -- CODE-VERIFIED LIKELY (default, feeds total) | C12: ='Pod Build'!$I$26+'Pod Build'!$I$27 -> 202.745 | D12: VERIFIED | E12: Sum of Specialist + Verifier lines (Pod Build rows 26-27) at the Control Panel's CODE-VERIFIED defaults (0.8K in / 0.25K out / 2 calls-item). llm_call_model.md SS3: ~$203/mo at Opus 4.8, 9,890 items/mo.
A13: Zone4 | B13: LLM tokens -- CLIENT-SKETCH HIGH (scenario only, NOT in total) | C13: =LlmItems*4*(50/1000*IF(ModelSKU="Opus-4.8",Rates!$C$121,IF(ModelSKU="Sonnet-5",Rates!$C$127,Rates!$C$133))+1/1000*IF(ModelSKU="Opus-4.8",Rates!$C$122,IF(ModelSKU="Sonnet-5",Rates!$C$128,Rates!$C$134))) -> 10879 | D13: ASSUMPTION | E13: Client's original sketch: 4 calls/item, 50K in / 1K out per call. Shown as a labelled scenario for comparison -- excluded from MonthlyTCO total. llm_call_model.md SS3 narrative.
A14: Zone4 | B14: LLM tokens -- DENSE-ARM OPTIONAL (default OFF, scenario only) | C14: ='Pod Build'!$I$28 -> 0 | D14: DERIVED | E14: Cross-links to Pod Build row 28 (opus_dense per taxonomy node); amber multiplier defaults 0 (off), matching deployed SCUDO_DENSE_BACKEND=jaro_winkler. llm_call_model.md SS1/SS3 (14-node demo fixture if enabled).
A15: Zone4 | B15: Bedrock Evaluations (judge -- folded into Specialist/Verifier tokens) | C15: ='Pod Build'!$I$29 -> 0 | D15: ASSUMPTION | E15: No separate meter; $0 incremental (Pod Build row 29).
A16: ZONE 5 -- PERSISTENCE / HITL
A17: Zone5 | B17: Outbox + AppSync + ECS + projection sink (Pod D total) | C17: ='Pod Build'!$I$30+'Pod Build'!$I$31+'Pod Build'!$I$32+'Pod Build'!$I$33+'Pod Build'!$I$34 -> 18.133318 | D17: DERIVED | E17: Cross-links to Pod Build Pod D rows 30-34.
A18: PLATFORM -- ALWAYS-ON (POD E)
A19: Platform | B19: FalkorDB + CloudFront + ALB + NAT + Secrets + VPC endpoints + CodeBuild | C19: ='Pod Build'!$I$35+'Pod Build'!$I$36+'Pod Build'!$I$37+'Pod Build'!$I$38+'Pod Build'!$I$39+'Pod Build'!$I$40+'Pod Build'!$I$41 -> 116.4551 | D19: DERIVED | E19: Cross-links to Pod Build Pod E rows 35-41.
A20: TOTALS
B21: Subtotal (excludes HIGH scenario row) | C21: =C5+C7+C9+C11+C12+C14+C15+C17+C19 -> 1251.5875
B22: Contingency uplift | C22: =C21*ContingencyPct -> 187.73812
B23: MONTHLY TCO (at Control Panel defaults) | C23: =C21+C22 -> 1439.3256

Sheet 12mo Run Cost
A1: 12-mo Run Cost -- ramp profile, Nov 2026 go-live
A2: ="Ramp: M1 "&TEXT(RampM1,"0%")&" / M2 "&TEXT(RampM2,"0%")&" / M3+ "&TEXT(RampM3Plus,"0%")&" of steady-state volume -- applies to volume-driven meters only. Always-on infra (Aurora, OpenSearch, ECS, NAT, ALB, endpoints) does not ramp." -> Ramp: M1 50% / M2 75% / M3+ 100% of steady-state volume -- applies to volume-driven meters only. Always-on infra (Aurora, OpenSearch, ECS, NAT, ALB, endpoints) does not ramp.
A3: Component | B3: Ramp class | C3: Nov 2026 | D3: Dec 2026 | E3: Jan 2027 | F3: Feb 2027 | G3: Mar 2027 | H3: Apr 2027 | I3: May 2027 | J3: Jun 2027 | K3: Jul 2027 | L3: Aug 2027 | M3: Sep 2027 | N3: Oct 2027 | O3: 12-mo Total
A4: Ramp % (of steady-state) -- editable | C4: 0.5 | D4: 0.75 | E4: 1 | F4: =E$4 -> 1 | G4: =E$4 -> 1 | H4: =E$4 -> 1 | I4: =E$4 -> 1 | J4: =E$4 -> 1 | K4: =E$4 -> 1 | L4: =E$4 -> 1 | M4: =E$4 -> 1 | N4: =E$4 -> 1
A5: Pod A: API GW entry + routing | B5: Ramps | C5: ='Pod Build'!$I$4*C$4 -> 0.0173075 | D5: ='Pod Build'!$I$4*D$4 -> 0.02596125 | E5: ='Pod Build'!$I$4*E$4 -> 0.034615 | F5: ='Pod Build'!$I$4*E$4 -> 0.034615 | G5: ='Pod Build'!$I$4*E$4 -> 0.034615 | H5: ='Pod Build'!$I$4*E$4 -> 0.034615 | I5: ='Pod Build'!$I$4*E$4 -> 0.034615 | J5: ='Pod Build'!$I$4*E$4 -> 0.034615 | K5: ='Pod Build'!$I$4*E$4 -> 0.034615 | L5: ='Pod Build'!$I$4*E$4 -> 0.034615 | M5: ='Pod Build'!$I$4*E$4 -> 0.034615 | N5: ='Pod Build'!$I$4*E$4 -> 0.034615 | O5: =SUM(C5:N5) -> 0.38941875
A6: Pod A: Lambda authorizer | B6: Ramps | C6: ='Pod Build'!$I$5*C$4 -> 0 | D6: ='Pod Build'!$I$5*D$4 -> 0 | E6: ='Pod Build'!$I$5*E$4 -> 0 | F6: ='Pod Build'!$I$5*E$4 -> 0 | G6: ='Pod Build'!$I$5*E$4 -> 0 | H6: ='Pod Build'!$I$5*E$4 -> 0 | I6: ='Pod Build'!$I$5*E$4 -> 0 | J6: ='Pod Build'!$I$5*E$4 -> 0 | K6: ='Pod Build'!$I$5*E$4 -> 0 | L6: ='Pod Build'!$I$5*E$4 -> 0 | M6: ='Pod Build'!$I$5*E$4 -> 0 | N6: ='Pod Build'!$I$5*E$4 -> 0 | O6: =SUM(C6:N6) -> 0
A7: Pod A: Ingestion Coordinator (ETL worker) | B7: Ramps | C7: ='Pod Build'!$I$6*C$4 -> 0.48518789 | D7: ='Pod Build'!$I$6*D$4 -> 0.72778183 | E7: ='Pod Build'!$I$6*E$4 -> 0.97037577 | F7: ='Pod Build'!$I$6*E$4 -> 0.97037577 | G7: ='Pod Build'!$I$6*E$4 -> 0.97037577 | H7: ='Pod Build'!$I$6*E$4 -> 0.97037577 | I7: ='Pod Build'!$I$6*E$4 -> 0.97037577 | J7: ='Pod Build'!$I$6*E$4 -> 0.97037577 | K7: ='Pod Build'!$I$6*E$4 -> 0.97037577 | L7: ='Pod Build'!$I$6*E$4 -> 0.97037577 | M7: ='Pod Build'!$I$6*E$4 -> 0.97037577 | N7: ='Pod Build'!$I$6*E$4 -> 0.97037577 | O7: =SUM(C7:N7) -> 10.916727
A8: Pod A: Sanity Check (validate/quarantine) | B8: Ramps | C8: ='Pod Build'!$I$7*C$4 -> 0 | D8: ='Pod Build'!$I$7*D$4 -> 0 | E8: ='Pod Build'!$I$7*E$4 -> 0 | F8: ='Pod Build'!$I$7*E$4 -> 0 | G8: ='Pod Build'!$I$7*E$4 -> 0 | H8: ='Pod Build'!$I$7*E$4 -> 0 | I8: ='Pod Build'!$I$7*E$4 -> 0 | J8: ='Pod Build'!$I$7*E$4 -> 0 | K8: ='Pod Build'!$I$7*E$4 -> 0 | L8: ='Pod Build'!$I$7*E$4 -> 0 | M8: ='Pod Build'!$I$7*E$4 -> 0 | N8: ='Pod Build'!$I$7*E$4 -> 0 | O8: =SUM(C8:N8) -> 0
A9: Pod A: CloudWatch (logs + metrics) | B9: Ramps | C9: ='Pod Build'!$I$8*C$4 -> 3.7552417 | D9: ='Pod Build'!$I$8*D$4 -> 5.6328626 | E9: ='Pod Build'!$I$8*E$4 -> 7.5104834 | F9: ='Pod Build'!$I$8*E$4 -> 7.5104834 | G9: ='Pod Build'!$I$8*E$4 -> 7.5104834 | H9: ='Pod Build'!$I$8*E$4 -> 7.5104834 | I9: ='Pod Build'!$I$8*E$4 -> 7.5104834 | J9: ='Pod Build'!$I$8*E$4 -> 7.5104834 | K9: ='Pod Build'!$I$8*E$4 -> 7.5104834 | L9: ='Pod Build'!$I$8*E$4 -> 7.5104834 | M9: ='Pod Build'!$I$8*E$4 -> 7.5104834 | N9: ='Pod Build'!$I$8*E$4 -> 7.5104834 | O9: =SUM(C9:N9) -> 84.492938
A10: Pod A: S3 raw landing | B10: Ramps | C10: ='Pod Build'!$I$9*C$4 -> 0.03041175 | D10: ='Pod Build'!$I$9*D$4 -> 0.045617625 | E10: ='Pod Build'!$I$9*E$4 -> 0.0608235 | F10: ='Pod Build'!$I$9*E$4 -> 0.0608235 | G10: ='Pod Build'!$I$9*E$4 -> 0.0608235 | H10: ='Pod Build'!$I$9*E$4 -> 0.0608235 | I10: ='Pod Build'!$I$9*E$4 -> 0.0608235 | J10: ='Pod Build'!$I$9*E$4 -> 0.0608235 | K10: ='Pod Build'!$I$9*E$4 -> 0.0608235 | L10: ='Pod Build'!$I$9*E$4 -> 0.0608235 | M10: ='Pod Build'!$I$9*E$4 -> 0.0608235 | N10: ='Pod Build'!$I$9*E$4 -> 0.0608235 | O10: =SUM(C10:N10) -> 0.68426438
A11: Pod A: EventBridge Scheduler (poller) | B11: Ramps | C11: ='Pod Build'!$I$10*C$4 -> 1e-06 | D11: ='Pod Build'!$I$10*D$4 -> 1.5e-06 | E11: ='Pod Build'!$I$10*E$4 -> 2e-06 | F11: ='Pod Build'!$I$10*E$4 -> 2e-06 | G11: ='Pod Build'!$I$10*E$4 -> 2e-06 | H11: ='Pod Build'!$I$10*E$4 -> 2e-06 | I11: ='Pod Build'!$I$10*E$4 -> 2e-06 | J11: ='Pod Build'!$I$10*E$4 -> 2e-06 | K11: ='Pod Build'!$I$10*E$4 -> 2e-06 | L11: ='Pod Build'!$I$10*E$4 -> 2e-06 | M11: ='Pod Build'!$I$10*E$4 -> 2e-06 | N11: ='Pod Build'!$I$10*E$4 -> 2e-06 | O11: =SUM(C11:N11) -> 2.25e-05
A12: Pod A: EventBridge ObjectCreated rule | B12: Ramps | C12: ='Pod Build'!$I$11*C$4 -> 0.004945 | D12: ='Pod Build'!$I$11*D$4 -> 0.0074175 | E12: ='Pod Build'!$I$11*E$4 -> 0.00989 | F12: ='Pod Build'!$I$11*E$4 -> 0.00989 | G12: ='Pod Build'!$I$11*E$4 -> 0.00989 | H12: ='Pod Build'!$I$11*E$4 -> 0.00989 | I12: ='Pod Build'!$I$11*E$4 -> 0.00989 | J12: ='Pod Build'!$I$11*E$4 -> 0.00989 | K12: ='Pod Build'!$I$11*E$4 -> 0.00989 | L12: ='Pod Build'!$I$11*E$4 -> 0.00989 | M12: ='Pod Build'!$I$11*E$4 -> 0.00989 | N12: ='Pod Build'!$I$11*E$4 -> 0.00989 | O12: =SUM(C12:N12) -> 0.1112625
A13: Pod A: SQS (EtlQueue + DLQ) | B13: Ramps | C13: ='Pod Build'!$I$12*C$4 -> 0.001978 | D13: ='Pod Build'!$I$12*D$4 -> 0.002967 | E13: ='Pod Build'!$I$12*E$4 -> 0.003956 | F13: ='Pod Build'!$I$12*E$4 -> 0.003956 | G13: ='Pod Build'!$I$12*E$4 -> 0.003956 | H13: ='Pod Build'!$I$12*E$4 -> 0.003956 | I13: ='Pod Build'!$I$12*E$4 -> 0.003956 | J13: ='Pod Build'!$I$12*E$4 -> 0.003956 | K13: ='Pod Build'!$I$12*E$4 -> 0.003956 | L13: ='Pod Build'!$I$12*E$4 -> 0.003956 | M13: ='Pod Build'!$I$12*E$4 -> 0.003956 | N13: ='Pod Build'!$I$12*E$4 -> 0.003956 | O13: =SUM(C13:N13) -> 0.044505
A14: Pod A: ETL worker VPC egress (NAT) | B14: Ramps | C14: ='Pod Build'!$I$13*C$4 -> 0 | D14: ='Pod Build'!$I$13*D$4 -> 0 | E14: ='Pod Build'!$I$13*E$4 -> 0 | F14: ='Pod Build'!$I$13*E$4 -> 0 | G14: ='Pod Build'!$I$13*E$4 -> 0 | H14: ='Pod Build'!$I$13*E$4 -> 0 | I14: ='Pod Build'!$I$13*E$4 -> 0 | J14: ='Pod Build'!$I$13*E$4 -> 0 | K14: ='Pod Build'!$I$13*E$4 -> 0 | L14: ='Pod Build'!$I$13*E$4 -> 0 | M14: ='Pod Build'!$I$13*E$4 -> 0 | N14: ='Pod Build'!$I$13*E$4 -> 0 | O14: =SUM(C14:N14) -> 0
A15: Pod A: S3 canonical sink | B15: Ramps | C15: ='Pod Build'!$I$14*C$4 -> 0.03041175 | D15: ='Pod Build'!$I$14*D$4 -> 0.045617625 | E15: ='Pod Build'!$I$14*E$4 -> 0.0608235 | F15: ='Pod Build'!$I$14*E$4 -> 0.0608235 | G15: ='Pod Build'!$I$14*E$4 -> 0.0608235 | H15: ='Pod Build'!$I$14*E$4 -> 0.0608235 | I15: ='Pod Build'!$I$14*E$4 -> 0.0608235 | J15: ='Pod Build'!$I$14*E$4 -> 0.0608235 | K15: ='Pod Build'!$I$14*E$4 -> 0.0608235 | L15: ='Pod Build'!$I$14*E$4 -> 0.0608235 | M15: ='Pod Build'!$I$14*E$4 -> 0.0608235 | N15: ='Pod Build'!$I$14*E$4 -> 0.0608235 | O15: =SUM(C15:N15) -> 0.68426438
A16: Pod A: S3 quarantine | B16: Ramps | C16: ='Pod Build'!$I$15*C$4 -> 0 | D16: ='Pod Build'!$I$15*D$4 -> 0 | E16: ='Pod Build'!$I$15*E$4 -> 0 | F16: ='Pod Build'!$I$15*E$4 -> 0 | G16: ='Pod Build'!$I$15*E$4 -> 0 | H16: ='Pod Build'!$I$15*E$4 -> 0 | I16: ='Pod Build'!$I$15*E$4 -> 0 | J16: ='Pod Build'!$I$15*E$4 -> 0 | K16: ='Pod Build'!$I$15*E$4 -> 0 | L16: ='Pod Build'!$I$15*E$4 -> 0 | M16: ='Pod Build'!$I$15*E$4 -> 0 | N16: ='Pod Build'!$I$15*E$4 -> 0 | O16: =SUM(C16:N16) -> 0
A17: Pod B: AIA Matching Engine gate A (scope) | B17: Ramps | C17: ='Pod Build'!$I$16*C$4 -> 0 | D17: ='Pod Build'!$I$16*D$4 -> 0 | E17: ='Pod Build'!$I$16*E$4 -> 0 | F17: ='Pod Build'!$I$16*E$4 -> 0 | G17: ='Pod Build'!$I$16*E$4 -> 0 | H17: ='Pod Build'!$I$16*E$4 -> 0 | I17: ='Pod Build'!$I$16*E$4 -> 0 | J17: ='Pod Build'!$I$16*E$4 -> 0 | K17: ='Pod Build'!$I$16*E$4 -> 0 | L17: ='Pod Build'!$I$16*E$4 -> 0 | M17: ='Pod Build'!$I$16*E$4 -> 0 | N17: ='Pod Build'!$I$16*E$4 -> 0 | O17: =SUM(C17:N17) -> 0
A18: Pod B: AIA Matching Engine gate B (precedent) | B18: Ramps | C18: ='Pod Build'!$I$17*C$4 -> 0 | D18: ='Pod Build'!$I$17*D$4 -> 0 | E18: ='Pod Build'!$I$17*E$4 -> 0 | F18: ='Pod Build'!$I$17*E$4 -> 0 | G18: ='Pod Build'!$I$17*E$4 -> 0 | H18: ='Pod Build'!$I$17*E$4 -> 0 | I18: ='Pod Build'!$I$17*E$4 -> 0 | J18: ='Pod Build'!$I$17*E$4 -> 0 | K18: ='Pod Build'!$I$17*E$4 -> 0 | L18: ='Pod Build'!$I$17*E$4 -> 0 | M18: ='Pod Build'!$I$17*E$4 -> 0 | N18: ='Pod Build'!$I$17*E$4 -> 0 | O18: =SUM(C18:N18) -> 0
A19: Pod B: AIA Matching Engine gate C (hybrid retrieval) | B19: Ramps | C19: ='Pod Build'!$I$18*C$4 -> 0 | D19: ='Pod Build'!$I$18*D$4 -> 0 | E19: ='Pod Build'!$I$18*E$4 -> 0 | F19: ='Pod Build'!$I$18*E$4 -> 0 | G19: ='Pod Build'!$I$18*E$4 -> 0 | H19: ='Pod Build'!$I$18*E$4 -> 0 | I19: ='Pod Build'!$I$18*E$4 -> 0 | J19: ='Pod Build'!$I$18*E$4 -> 0 | K19: ='Pod Build'!$I$18*E$4 -> 0 | L19: ='Pod Build'!$I$18*E$4 -> 0 | M19: ='Pod Build'!$I$18*E$4 -> 0 | N19: ='Pod Build'!$I$18*E$4 -> 0 | O19: =SUM(C19:N19) -> 0
A20: Pod B: Titan Embeddings (indexing/write path) | B20: Ramps | C20: ='Pod Build'!$I$19*C$4 -> 0.04945 | D20: ='Pod Build'!$I$19*D$4 -> 0.074175 | E20: ='Pod Build'!$I$19*E$4 -> 0.0989 | F20: ='Pod Build'!$I$19*E$4 -> 0.0989 | G20: ='Pod Build'!$I$19*E$4 -> 0.0989 | H20: ='Pod Build'!$I$19*E$4 -> 0.0989 | I20: ='Pod Build'!$I$19*E$4 -> 0.0989 | J20: ='Pod Build'!$I$19*E$4 -> 0.0989 | K20: ='Pod Build'!$I$19*E$4 -> 0.0989 | L20: ='Pod Build'!$I$19*E$4 -> 0.0989 | M20: ='Pod Build'!$I$19*E$4 -> 0.0989 | N20: ='Pod Build'!$I$19*E$4 -> 0.0989 | O20: =SUM(C20:N20) -> 1.112625
A21: Pod B: OpenSearch fuzzy+kNN | B21: Always-on | C21: ='Pod Build'!$I$20 -> 129.9705 | D21: ='Pod Build'!$I$20 -> 129.9705 | E21: ='Pod Build'!$I$20 -> 129.9705 | F21: ='Pod Build'!$I$20 -> 129.9705 | G21: ='Pod Build'!$I$20 -> 129.9705 | H21: ='Pod Build'!$I$20 -> 129.9705 | I21: ='Pod Build'!$I$20 -> 129.9705 | J21: ='Pod Build'!$I$20 -> 129.9705 | ... N21: ='Pod Build'!$I$20 -> 129.9705 | O21: =SUM(C21:N21) -> 1559.646
A22: Pod B: Aurora 2xlarge (system of record) | B22: Always-on | C22: ='Pod Build'!$I$21 -> 757.74 | D22: ='Pod Build'!$I$21 -> 757.74 | E22: ='Pod Build'!$I$21 -> 757.74 | F22: ='Pod Build'!$I$21 -> 757.74 | G22: ='Pod Build'!$I$21 -> 757.74 | H22: ='Pod Build'!$I$21 -> 757.74 | I22: ='Pod Build'!$I$21 -> 757.74 | J22: ='Pod Build'!$I$21 -> 757.74 | ... N22: ='Pod Build'!$I$21 -> 757.74 | O22: =SUM(C22:N22) -> 9092.88
A23: Pod C: Strands Orchestrator Opus 4.8 | B23: Ramps | C23: ='Pod Build'!$I$22*C$4 -> 0.24308844 | D23: ='Pod Build'!$I$22*D$4 -> 0.36463266 | E23: ='Pod Build'!$I$22*E$4 -> 0.48617689 | F23: ='Pod Build'!$I$22*E$4 -> 0.48617689 | G23: ='Pod Build'!$I$22*E$4 -> 0.48617689 | H23: ='Pod Build'!$I$22*E$4 -> 0.48617689 | I23: ='Pod Build'!$I$22*E$4 -> 0.48617689 | J23: ='Pod Build'!$I$22*E$4 -> 0.48617689 | K23: ='Pod Build'!$I$22*E$4 -> 0.48617689 | L23: ='Pod Build'!$I$22*E$4 -> 0.48617689 | M23: ='Pod Build'!$I$22*E$4 -> 0.48617689 | N23: ='Pod Build'!$I$22*E$4 -> 0.48617689 | O23: =SUM(C23:N23) -> 5.46949
A24: Pod C: AgentCore Memory (short-term events) | B24: Ramps | C24: ='Pod Build'!$I$23*C$4 -> 2.4725 | D24: ='Pod Build'!$I$23*D$4 -> 3.70875 | E24: ='Pod Build'!$I$23*E$4 -> 4.945 | F24: ='Pod Build'!$I$23*E$4 -> 4.945 | G24: ='Pod Build'!$I$23*E$4 -> 4.945 | H24: ='Pod Build'!$I$23*E$4 -> 4.945 | I24: ='Pod Build'!$I$23*E$4 -> 4.945 | J24: ='Pod Build'!$I$23*E$4 -> 4.945 | K24: ='Pod Build'!$I$23*E$4 -> 4.945 | L24: ='Pod Build'!$I$23*E$4 -> 4.945 | M24: ='Pod Build'!$I$23*E$4 -> 4.945 | N24: ='Pod Build'!$I$23*E$4 -> 4.945 | O24: =SUM(C24:N24) -> 55.63125
A25: Pod C: AgentCore Memory (long-term records) | B25: Ramps | C25: ='Pod Build'!$I$24*C$4 -> 3.70875 | D25: ='Pod Build'!$I$24*D$4 -> 5.563125 | E25: ='Pod Build'!$I$24*E$4 -> 7.4175 | F25: ='Pod Build'!$I$24*E$4 -> 7.4175 | G25: ='Pod Build'!$I$24*E$4 -> 7.4175 | H25: ='Pod Build'!$I$24*E$4 -> 7.4175 | I25: ='Pod Build'!$I$24*E$4 -> 7.4175 | J25: ='Pod Build'!$I$24*E$4 -> 7.4175 | K25: ='Pod Build'!$I$24*E$4 -> 7.4175 | L25: ='Pod Build'!$I$24*E$4 -> 7.4175 | M25: ='Pod Build'!$I$24*E$4 -> 7.4175 | N25: ='Pod Build'!$I$24*E$4 -> 7.4175 | O25: =SUM(C25:N25) -> 83.446875
A26: Pod C: AgentCore Memory (long-term retrieval) | B26: Ramps | C26: ='Pod Build'!$I$25*C$4 -> 2.4725 | D26: ='Pod Build'!$I$25*D$4 -> 3.70875 | E26: ='Pod Build'!$I$25*E$4 -> 4.945 | F26: ='Pod Build'!$I$25*E$4 -> 4.945 | G26: ='Pod Build'!$I$25*E$4 -> 4.945 | H26: ='Pod Build'!$I$25*E$4 -> 4.945 | I26: ='Pod Build'!$I$25*E$4 -> 4.945 | J26: ='Pod Build'!$I$25*E$4 -> 4.945 | K26: ='Pod Build'!$I$25*E$4 -> 4.945 | L26: ='Pod Build'!$I$25*E$4 -> 4.945 | M26: ='Pod Build'!$I$25*E$4 -> 4.945 | N26: ='Pod Build'!$I$25*E$4 -> 4.945 | O26: =SUM(C26:N26) -> 55.63125
A27: Pod C: Specialist agent (mapping) | B27: Ramps | C27: ='Pod Build'!$I$26*C$4 -> 50.68625 | D27: ='Pod Build'!$I$26*D$4 -> 76.029375 | E27: ='Pod Build'!$I$26*E$4 -> 101.3725 | F27: ='Pod Build'!$I$26*E$4 -> 101.3725 | G27: ='Pod Build'!$I$26*E$4 -> 101.3725 | H27: ='Pod Build'!$I$26*E$4 -> 101.3725 | I27: ='Pod Build'!$I$26*E$4 -> 101.3725 | J27: ='Pod Build'!$I$26*E$4 -> 101.3725 | K27: ='Pod Build'!$I$26*E$4 -> 101.3725 | L27: ='Pod Build'!$I$26*E$4 -> 101.3725 | M27: ='Pod Build'!$I$26*E$4 -> 101.3725 | N27: ='Pod Build'!$I$26*E$4 -> 101.3725 | O27: =SUM(C27:N27) -> 1140.4406
A28: Pod C: Verifier agent 10-dim | B28: Ramps | C28: ='Pod Build'!$I$27*C$4 -> 50.68625 | D28: ='Pod Build'!$I$27*D$4 -> 76.029375 | E28: ='Pod Build'!$I$27*E$4 -> 101.3725 | F28: ='Pod Build'!$I$27*E$4 -> 101.3725 | G28: ='Pod Build'!$I$27*E$4 -> 101.3725 | H28: ='Pod Build'!$I$27*E$4 -> 101.3725 | I28: ='Pod Build'!$I$27*E$4 -> 101.3725 | J28: ='Pod Build'!$I$27*E$4 -> 101.3725 | K28: ='Pod Build'!$I$27*E$4 -> 101.3725 | L28: ='Pod Build'!$I$27*E$4 -> 101.3725 | M28: ='Pod Build'!$I$27*E$4 -> 101.3725 | N28: ='Pod Build'!$I$27*E$4 -> 101.3725 | O28: =SUM(C28:N28) -> 1140.4406
A29: Pod C: Dense-arm optional (opus_dense per node) | B29: Ramps | C29: ='Pod Build'!$I$28*C$4 -> 0 | D29: ='Pod Build'!$I$28*D$4 -> 0 | E29: ='Pod Build'!$I$28*E$4 -> 0 | F29: ='Pod Build'!$I$28*E$4 -> 0 | G29: ='Pod Build'!$I$28*E$4 -> 0 | H29: ='Pod Build'!$I$28*E$4 -> 0 | I29: ='Pod Build'!$I$28*E$4 -> 0 | J29: ='Pod Build'!$I$28*E$4 -> 0 | K29: ='Pod Build'!$I$28*E$4 -> 0 | L29: ='Pod Build'!$I$28*E$4 -> 0 | M29: ='Pod Build'!$I$28*E$4 -> 0 | N29: ='Pod Build'!$I$28*E$4 -> 0 | O29: =SUM(C29:N29) -> 0
A30: Pod C: Bedrock Evaluations (judge) | B30: Ramps | C30: ='Pod Build'!$I$29*C$4 -> 0 | D30: ='Pod Build'!$I$29*D$4 -> 0 | E30: ='Pod Build'!$I$29*E$4 -> 0 | F30: ='Pod Build'!$I$29*E$4 -> 0 | G30: ='Pod Build'!$I$29*E$4 -> 0 | H30: ='Pod Build'!$I$29*E$4 -> 0 | I30: ='Pod Build'!$I$29*E$4 -> 0 | J30: ='Pod Build'!$I$29*E$4 -> 0 | K30: ='Pod Build'!$I$29*E$4 -> 0 | L30: ='Pod Build'!$I$29*E$4 -> 0 | M30: ='Pod Build'!$I$29*E$4 -> 0 | N30: ='Pod Build'!$I$29*E$4 -> 0 | O30: =SUM(C30:N30) -> 0
A31: Pod D: JAPI Persist outbox writer | B31: Ramps | C31: ='Pod Build'!$I$30*C$4 -> 0 | D31: ='Pod Build'!$I$30*D$4 -> 0 | E31: ='Pod Build'!$I$30*E$4 -> 0 | F31: ='Pod Build'!$I$30*E$4 -> 0 | G31: ='Pod Build'!$I$30*E$4 -> 0 | H31: ='Pod Build'!$I$30*E$4 -> 0 | I31: ='Pod Build'!$I$30*E$4 -> 0 | J31: ='Pod Build'!$I$30*E$4 -> 0 | K31: ='Pod Build'!$I$30*E$4 -> 0 | L31: ='Pod Build'!$I$30*E$4 -> 0 | M31: ='Pod Build'!$I$30*E$4 -> 0 | N31: ='Pod Build'!$I$30*E$4 -> 0 | O31: =SUM(C31:N31) -> 0
A32: Pod D: Outbox sweep (EventBridge Schedule) | B32: Ramps | C32: ='Pod Build'!$I$31*C$4 -> 0.004464 | D32: ='Pod Build'!$I$31*D$4 -> 0.006696 | E32: ='Pod Build'!$I$31*E$4 -> 0.008928 | F32: ='Pod Build'!$I$31*E$4 -> 0.008928 | G32: ='Pod Build'!$I$31*E$4 -> 0.008928 | H32: ='Pod Build'!$I$31*E$4 -> 0.008928 | I32: ='Pod Build'!$I$31*E$4 -> 0.008928 | J32: ='Pod Build'!$I$31*E$4 -> 0.008928 | K32: ='Pod Build'!$I$31*E$4 -> 0.008928 | L32: ='Pod Build'!$I$31*E$4 -> 0.008928 | M32: ='Pod Build'!$I$31*E$4 -> 0.008928 | N32: ='Pod Build'!$I$31*E$4 -> 0.008928 | O32: =SUM(C32:N32) -> 0.10044
A33: Pod D: HITL AppSync API | B33: Ramps | C33: ='Pod Build'!$I$32*C$4 -> 0.017802 | D33: ='Pod Build'!$I$32*D$4 -> 0.026703 | E33: ='Pod Build'!$I$32*E$4 -> 0.035604 | F33: ='Pod Build'!$I$32*E$4 -> 0.035604 | G33: ='Pod Build'!$I$32*E$4 -> 0.035604 | H33: ='Pod Build'!$I$32*E$4 -> 0.035604 | I33: ='Pod Build'!$I$32*E$4 -> 0.035604 | J33: ='Pod Build'!$I$32*E$4 -> 0.035604 | K33: ='Pod Build'!$I$32*E$4 -> 0.035604 | L33: ='Pod Build'!$I$32*E$4 -> 0.035604 | M33: ='Pod Build'!$I$32*E$4 -> 0.035604 | N33: ='Pod Build'!$I$32*E$4 -> 0.035604 | O33: =SUM(C33:N33) -> 0.400545
A34: Pod D: HITL review ECS task (reviewer console) | B34: Always-on | C34: ='Pod Build'!$I$33 -> 18.02005 | D34: ='Pod Build'!$I$33 -> 18.02005 | E34: ='Pod Build'!$I$33 -> 18.02005 | F34: ='Pod Build'!$I$33 -> 18.02005 | G34: ='Pod Build'!$I$33 -> 18.02005 | H34: ='Pod Build'!$I$33 -> 18.02005 | I34: ='Pod Build'!$I$33 -> 18.02005 | J34: ='Pod Build'!$I$33 -> 18.02005 | ... N34: ='Pod Build'!$I$33 -> 18.02005 | O34: =SUM(C34:N34) -> 216.2406
A35: Pod D: S3 projection sink + CloudFront invalidation | B35: Ramps | C35: ='Pod Build'!$I$34*C$4 -> 0.03436775 | D35: ='Pod Build'!$I$34*D$4 -> 0.051551625 | E35: ='Pod Build'!$I$34*E$4 -> 0.0687355 | F35: ='Pod Build'!$I$34*E$4 -> 0.0687355 | G35: ='Pod Build'!$I$34*E$4 -> 0.0687355 | H35: ='Pod Build'!$I$34*E$4 -> 0.0687355 | I35: ='Pod Build'!$I$34*E$4 -> 0.0687355 | J35: ='Pod Build'!$I$34*E$4 -> 0.0687355 | K35: ='Pod Build'!$I$34*E$4 -> 0.0687355 | L35: ='Pod Build'!$I$34*E$4 -> 0.0687355 | M35: ='Pod Build'!$I$34*E$4 -> 0.0687355 | N35: ='Pod Build'!$I$34*E$4 -> 0.0687355 | O35: =SUM(C35:N35) -> 0.77327438
A36: Pod E: FalkorDB on ECS (retrieval store) | B36: Always-on | C36: ='Pod Build'!$I$35 -> 36.0401 | D36: ='Pod Build'!$I$35 -> 36.0401 | E36: ='Pod Build'!$I$35 -> 36.0401 | F36: ='Pod Build'!$I$35 -> 36.0401 | G36: ='Pod Build'!$I$35 -> 36.0401 | H36: ='Pod Build'!$I$35 -> 36.0401 | I36: ='Pod Build'!$I$35 -> 36.0401 | J36: ='Pod Build'!$I$35 -> 36.0401 | ... N36: ='Pod Build'!$I$35 -> 36.0401 | O36: =SUM(C36:N36) -> 432.4812
A37: Pod E: CloudFront distribution | B37: Ramps | C37: ='Pod Build'!$I$36*C$4 -> 0.45 | D37: ='Pod Build'!$I$36*D$4 -> 0.675 | E37: ='Pod Build'!$I$36*E$4 -> 0.9 | F37: ='Pod Build'!$I$36*E$4 -> 0.9 | G37: ='Pod Build'!$I$36*E$4 -> 0.9 | H37: ='Pod Build'!$I$36*E$4 -> 0.9 | I37: ='Pod Build'!$I$36*E$4 -> 0.9 | J37: ='Pod Build'!$I$36*E$4 -> 0.9 | K37: ='Pod Build'!$I$36*E$4 -> 0.9 | L37: ='Pod Build'!$I$36*E$4 -> 0.9 | M37: ='Pod Build'!$I$36*E$4 -> 0.9 | N37: ='Pod Build'!$I$36*E$4 -> 0.9 | O37: =SUM(C37:N37) -> 10.125
A38: Pod E: ALB (console + API ingress) | B38: Always-on | C38: ='Pod Build'!$I$37 -> 22.265 | D38: ='Pod Build'!$I$37 -> 22.265 | E38: ='Pod Build'!$I$37 -> 22.265 | F38: ='Pod Build'!$I$37 -> 22.265 | G38: ='Pod Build'!$I$37 -> 22.265 | H38: ='Pod Build'!$I$37 -> 22.265 | I38: ='Pod Build'!$I$37 -> 22.265 | J38: ='Pod Build'!$I$37 -> 22.265 | ... N38: ='Pod Build'!$I$37 -> 22.265 | O38: =SUM(C38:N38) -> 267.18
A39: Pod E: NAT Gateway (VPC egress) | B39: Always-on | C39: ='Pod Build'!$I$38 -> 33.75 | D39: ='Pod Build'!$I$38 -> 33.75 | E39: ='Pod Build'!$I$38 -> 33.75 | F39: ='Pod Build'!$I$38 -> 33.75 | G39: ='Pod Build'!$I$38 -> 33.75 | H39: ='Pod Build'!$I$38 -> 33.75 | I39: ='Pod Build'!$I$38 -> 33.75 | J39: ='Pod Build'!$I$38 -> 33.75 | ... N39: ='Pod Build'!$I$38 -> 33.75 | O39: =SUM(C39:N39) -> 405
A40: Pod E: Secrets Manager (DB + API creds) | B40: Always-on | C40: ='Pod Build'!$I$39 -> 1.6 | D40: ='Pod Build'!$I$39 -> 1.6 | E40: ='Pod Build'!$I$39 -> 1.6 | F40: ='Pod Build'!$I$39 -> 1.6 | G40: ='Pod Build'!$I$39 -> 1.6 | H40: ='Pod Build'!$I$39 -> 1.6 | I40: ='Pod Build'!$I$39 -> 1.6 | J40: ='Pod Build'!$I$39 -> 1.6 | ... N40: ='Pod Build'!$I$39 -> 1.6 | O40: =SUM(C40:N40) -> 19.2
...

Sheet Gantt
A1: Gantt -- 14-week core (Pod lanes, parallel after 2-week foundation)
