Workbook
Name Agent_AGT_CAPEX: Agents!$F$6
Name Agent_AGT_GROWTH: Agents!$F$7
Name Agent_AGT_METER: Agents!$F$8
Name Agent_AGT_OPEX: Agents!$F$5
Name Agent_AGT_ORCH: Agents!$F$11
Name Agent_AGT_R1_CONTENT: Agents!$F$10
Name Agent_AGT_RECON: Agents!$F$9
Name AgentCount: 'Control Panel>>>'!$B$22
Name AgentStack: 'Control Panel>>>'!$B$20
Name AgentStackAgentY1: '5yr Run Cost'!$F$66
Name AgentStackFixedY1: '5yr Run Cost'!$F$67
Name AgentStackMcpY1: '5yr Run Cost'!$F$65
Name AgentStackRunY1: '5yr Run Cost'!$F$64
Name ClusterCount: 'Control Panel>>>'!$B$9
Name ContingencyPct: 'Control Panel>>>'!$B$12
Name DayRate: 'Control Panel>>>'!$B$11
Name EffortBasis: 'Control Panel>>>'!$B$6
Name EnvCount: 'Control Panel>>>'!$B$8
Name GanttCorrGoLive: 'Gantt - Revised'!$BX$4
Name GanttFixedEnd: 'Gantt - POAP As Drawn'!$J$192
Name GanttFoldFixedEnd: 'Gantt - POAP As Drawn'!$J$147
Name GanttGoLive: 'Gantt - POAP As Drawn'!$BW$4
Name GanttParentEnd: 'Gantt - POAP As Drawn'!$J$147
Name GanttParentStart: 'Gantt - POAP As Drawn'!$I$147
Name GanttProbeEnd: 'Gantt - POAP As Drawn'!$J$6
Name GanttStepEnd: 'Gantt - POAP As Drawn'!$J$152
Name GanttStepStart: 'Gantt - POAP As Drawn'!$I$152
Name GoLiveDate: Overview!$B$26
Name GoLiveWeek: Overview!$B$25
Name HCL_Toggle: 'Control Panel>>>'!$B$5
Name Indexation: 'Control Panel>>>'!$B$13
Name McpServerCount: 'Control Panel>>>'!$B$23
Name ModelSKU: 'Control Panel>>>'!$B$19
Name ModelVendor: 'Control Panel>>>'!$B$18
Name NodeSize: 'Control Panel>>>'!$B$10
Name Observability: 'Control Panel>>>'!$B$17
Name OrgSize: 'Control Panel>>>'!$B$16
Name OverlapWeeks: 'Control Panel>>>'!$B$15
Name PilotTotal: 'R1 Pilot'!$I$17
Name Platform: 'Control Panel>>>'!$B$7
Name RagMemoryShape: 'Control Panel>>>'!$B$21
Name RefStackY1_1x2: Overview!$D$41
Name RefStackY1_30x50: Overview!$D$43
Name RefStackY1_5x10: Overview!$D$42
Name RunY1: '5yr Run Cost'!$F$63
Name RunY2: '5yr Run Cost'!$G$63
Name RunY3: '5yr Run Cost'!$H$63
Name RunY4: '5yr Run Cost'!$I$63
Name RunY5: '5yr Run Cost'!$J$63
Name SlipWeeks: 'Control Panel>>>'!$B$14
Name TotalBuild: 'POAP Build Cost'!$I$102
Name TotalRun5yr: '5yr Run Cost'!$K$63
Name WeeklyBurn: 'POAP Build Cost'!$I$99

Sheet Overview
A1: SEGRO POAP Costings — Summary (all figures recalc live from the Control Panel)
A2: ="Active scenario: effort = "&EffortBasis&" · HCL = "&HCL_Toggle&" · platform = "&Platform&" · vendor = "&ModelVendor&" · sku = "&ModelSKU&" · obs = "&Observability&" · agents = "&AgentStack&"/"&AgentCount&" · mcp = "&McpServerCount&" · rag = "&RagMemoryShape&" · envs = "&EnvCount&" · day rate £"&TEXT(DayRate,"#,##0")&" · contingency "&TEXT(ContingencyPct,"0%")&" · slip "&SlipWeeks&" wk · overlap "&OverlapWeeks&" wk" -> Active scenario: effort = Likely · HCL = Include · platform = AKS · vendor = AzureOpenAI · sku = GPT-4o · obs = Azure · agents = Exclude/1 · mcp = 2 · rag = AISearch_Cosmos · envs = 4 · day rate £850 · contingency 15% · slip 0 wk · overlap 0 wk
A4: HEADLINES
A5: Build — POAP phases + loadings (one-off) | B5: =TotalBuild -> 830342.07
A6: Run — 5 years (indexed) | B6: =TotalRun5yr -> 1656842.3
A7: 5-YEAR TCO (build + run) | B7: =TotalBuild+TotalRun5yr -> 2487184.4
A8: TCO per employee (OrgSize input) | B8: =(TotalBuild+TotalRun5yr)/OrgSize -> 3553.1206
A9: Y1 cash (build + run Y1) | B9: =TotalBuild+RunY1 -> 1142415.9
A11: CHART DATA (formula-driven — edit the Control Panel, not these cells)
A12: Waterfall segment | B12: Base (invisible) | C12: Block (visible) | D12: Delta (signed) | E12: Cumulative | F12: Short label | H12: Reverse label | I12: Base (invisible) | J12: Block (visible) | K12: Cumulative (reverse)
A13: Design & Plan | B13: 0 | C13: =D13 -> 66625 | D13: ='POAP Build Cost'!I15 -> 66625 | E13: =D13 -> 66625 | F13: Plan | H13: =F22 -> 5-yr TCO | I13: 0 | J13: =D22 -> 2487184.4 | K13: =I13+J13 -> 2487184.4
A14: Build - SEGRO (Azure foundations, AKS, shared services) | B14: =MIN(E13,E14) -> 66625 | C14: =ABS(D14) -> 221146.58 | D14: ='POAP Build Cost'!I50 -> 221146.58 | E14: =E13+D14 -> 287771.58 | F14: Build | H14: =F13 -> Plan | I14: =K14 -> 2420559.4 | J14: =D13 -> 66625 | K14: =K13-D13 -> 2420559.4
A15: Build - HCL (UnO + TX install, Unica+/CDP deploy) | B15: =MIN(E14,E15) -> 287771.58 | C15: =ABS(D15) -> 158250 | D15: ='POAP Build Cost'!I62 -> 158250 | E15: =E14+D15 -> 446021.58 | F15: Build | H15: =F14 -> Build | I15: =K15 -> 2199412.8 | J15: =D14 -> 221146.58 | K15: =K14-D14 -> 2199412.8
A16: Testing (SIT, pen test, UAT, performance) | B16: =MIN(E15,E16) -> 446021.58 | C16: =ABS(D16) -> 89165 | D16: ='POAP Build Cost'!I75 -> 89165 | E16: =E15+D16 -> 535186.58 | F16: Testing | H16: =F15 -> Build | I16: =K16 -> 2041162.8 | J16: =D15 -> 158250 | K16: =K15-D15 -> 2041162.8
A17: Deploy (prod readiness, migration, go-live) | B17: =MIN(E16,E17) -> 535186.58 | C17: =ABS(D17) -> 66700 | D17: ='POAP Build Cost'!I85 -> 66700 | E17: =E16+D17 -> 601886.58 | F17: Deploy | H17: =F16 -> Testing | I17: =K17 -> 1951997.8 | J17: =D16 -> 89165 | K17: =K16-D16 -> 1951997.8
A18: Hypercare / PGLS + business readiness close-out | B18: =MIN(E17,E18) -> 601886.58 | C18: =ABS(D18) -> 120150 | D18: ='POAP Build Cost'!I94 -> 120150 | E18: =E17+D18 -> 722036.58 | F18: Maintenance | H18: =F17 -> Deploy | I18: =K18 -> 1885297.8 | J18: =D17 -> 66700 | K18: =K17-D17 -> 1885297.8
A19: Contingency | B19: =MIN(E18,E19) -> 722036.58 | C19: =ABS(D19) -> 108305.49 | D19: ='POAP Build Cost'!I98 -> 108305.49 | E19: =E18+D19 -> 830342.07 | F19: Contingency | H19: =F18 -> Maintenance | I19: =K19 -> 1765147.8 | J19: =D18 -> 120150 | K19: =K18-D18 -> 1765147.8
A20: Slip − Overlap | B20: =MIN(E19,E20) -> 830342.07 | C20: =ABS(D20) -> 0 | D20: ='POAP Build Cost'!I100+'POAP Build Cost'!I101 -> 0 | E20: =E19+D20 -> 830342.07 | F20: Slip/Overlap | H20: =F19 -> Contingency | I20: =K20 -> 1656842.3 | J20: =D19 -> 108305.49 | K20: =K19-D19 -> 1656842.3
A21: Run (5yr) | B21: =MIN(E20,E21) -> 830342.07 | C21: =ABS(D21) -> 1656842.3 | D21: =TotalRun5yr -> 1656842.3 | E21: =E20+D21 -> 2487184.4 | F21: Run (5yr) | H21: =F20 -> Slip/Overlap | I21: =K21 -> 1656842.3 | J21: =D20 -> 0 | K21: =K20-D20 -> 1656842.3
A22: 5-yr TCO | B22: 0 | C22: =D22 -> 2487184.4 | D22: =TotalBuild+TotalRun5yr -> 2487184.4 | E22: =D22 -> 2487184.4 | F22: 5-yr TCO | H22: =F21 -> Run (5yr) | I22: =K22 -> 0 | J22: =D21 -> 1656842.3 | K22: =K21-D21 -> 0
A24: GO-LIVE (live — moves with slip)
A25: Live go-live week (29 + slip) | B25: =MAX(1,29+SlipWeeks) -> 29 | D25: Nominal 29 wk (Fri wk29 = 29 Jan 2027); slip extends go-live. Overlap is a cost saving (parallel HCL install), not a critical-path compression — matches the Gantt.
A26: Live go-live date | B26: =DATE(2026,7,13)+((GoLiveWeek-1)*7+4) -> 46416 | D26: Anchored to the Gantt week-1 Monday (13 Jul 2026); Friday of the live go-live week.
A28: GO-LIVE SCENARIOS (Green Book duration band) | B28: Optimistic | C28: Green Book lower | D28: Green Book upper
A29: Slip applied (weeks) | B29: 0 | C29: 3 | D29: 16
A30: Go-live week | B30: =29+0 -> 29 | C30: =29+3 -> 32 | D30: =29+16 -> 45
A31: Go-live date | B31: =DATE(2026,7,13)+((29+0-1)*7+4) -> 46416 | C31: =DATE(2026,7,13)+((29+3-1)*7+4) -> 46437 | D31: =DATE(2026,7,13)+((29+16-1)*7+4) -> 46528
A32: Weeks later than plan | B32: 0 | C32: 3 | D32: 16
A33: ▪ Scenarios hold overlap at 0. +3 wk ≈ Green Book ICT duration optimism-bias lower bound (+10% of the 29-wk pre-go-live span); +16 wk ≈ upper bound (+54%). The live figures above respond to the actual Control Panel slip/overlap.
A35: AGENT / MCP CALCULATOR (live — edit Control Panel)
A36: AgentStack | B36: =AgentStack -> Exclude | C36: RagMemoryShape | D36: =RagMemoryShape -> AISearch_Cosmos
A37: AgentCount (intensity) | B37: =AgentCount -> 1 | C37: McpServerCount (app plugs) | D37: =McpServerCount -> 2
A38: Agent-stack run Y1 (MCP+RAG+memory; £0 when AgentStack=Exclude) | B38: =IFERROR(AgentStackRunY1,0) -> 0
A40: Reference scenarios (proportional from live stack Y1; does not override Control Panel) | B40: Agents | C40: MCP servers | D40: Est. stack Y1 £
A41: Scenario 1 agents × 2 MCP | B41: 1 | C41: 2 | D41: =IF(OR(AgentStack="Exclude",AgentCount=0,McpServerCount=0),0,IFERROR(AgentStackMcpY1*(2/McpServerCount)+AgentStackAgentY1*(1/AgentCount)+AgentStackFixedY1,0)) -> 0
A42: Scenario 5 agents × 10 MCP | B42: 5 | C42: 10 | D42: =IF(OR(AgentStack="Exclude",AgentCount=0,McpServerCount=0),0,IFERROR(AgentStackMcpY1*(10/McpServerCount)+AgentStackAgentY1*(5/AgentCount)+AgentStackFixedY1,0)) -> 0
A43: Scenario 30 agents × 50 MCP | B43: 30 | C43: 50 | D43: =IF(OR(AgentStack="Exclude",AgentCount=0,McpServerCount=0),0,IFERROR(AgentStackMcpY1*(50/McpServerCount)+AgentStackAgentY1*(30/AgentCount)+AgentStackFixedY1,0)) -> 0
A44: ▪ Named agents (which to build) live on the Agents tab and Gantt ASSUMPTION lanes. AgentCount scales intensity; McpServerCount scales application plugs.
A46: Month (from contract) | B46: Cumulative spend £ | C46: Go-live marker
A47: 1 | B47: =MAX(0,MIN(MIN(1*4.33,(GoLiveWeek+6))-0*(GoLiveWeek/29),5*(GoLiveWeek/29)))/(5*(GoLiveWeek/29))*'POAP Build Cost'!I15+MAX(0,MIN(MIN(1*4.33,(GoLiveWeek+6))-5*(GoLiveWeek/29),10*(GoLiveWeek/29)))/(10*(GoLiveWeek/29))*'POAP Build Cost'!I50+MAX(0,MIN(MIN(1*4.33,(GoLiveWeek+6))-15*(GoLiveWeek/29),6*(GoLiveWeek/29)))/(6*(GoLiveWeek/29))*'POAP Build Cost'!I62+MAX(0,MIN(MIN(1*4.33,(GoLiveWeek+6))-21*(GoLiveWeek/29),4*(GoLiveWeek/29)))/(4*(GoLiveWeek/29))*'POAP Build Cost'!I75+MAX(0,MIN(MIN(1*4.33,(GoLiveWeek+6))-25*(GoLiveWeek/29),4*(GoLiveWeek/29)))/(4*(GoLiveWeek/29))*'POAP Build Cost'!I85+MAX(0,MIN(MIN(1*4.33,(GoLiveWeek+6))-GoLiveWeek,6))/6*'POAP Build Cost'!I94+MIN(MIN(1*4.33,(GoLiveWeek+6)),GoLiveWeek)/GoLiveWeek*('POAP Build Cost'!I98+'POAP Build Cost'!I100+'POAP Build Cost'!I101)+MAX(0,1*4.33-GoLiveWeek)/4.33/12*RunY1 -> 73868.38 | C47: =IF(1=ROUNDUP(GoLiveWeek/4.33,0),B47,NA()) -> #N/A
...

Sheet Gantt - POAP As Drawn
A1: Gantt - POAP As Drawn — technical step decomposition per major line of work
A2: The POAP as drawn on slide 3 (16 Jul 2026 deck), decomposed into technical steps per major line of work. Window statuses: POAP-DRAWN = bar drawn on the slide; ASSUMPTION = no bar exists (the work is costed but absent from the plan). Step statuses: DERIVED = step text and position follow from slide sub-items, named documents (slides 5-10) or the verified cost model; ASSUMPTION = position is sequencing judgement, text still sourced. TASK bars dilate with SlipWeeks ONLY on time-driven work (people schedules + Azure commissioning + any people LANE); a pure fixed-fee TASK bar (a RATE_MISSING-licence fold or a third-party pen-test/red-team engagement) SHIFTS under slip but keeps its drawn duration, matching the slip-cost model. STEP bars render RELATIVE to their parent task's live window, so a fixed licence STEP inside a time-driven lane (e.g. the procurement track) rides the lane and may widen with it — the fixed-does-not-stretch rule is a TASK-row property, not a step-row one. Bars recalc live: SlipWeeks dilates TIME-DRIVEN windows (people + Azure commissioning) pro-rata — the same elongation the slip cost prices; FIXED-fee engagements (licences, third-party pen-test/red-team) shift but keep their duration; hypercare shifts whole. A ▶ in the Slip column flags any bar clipped at the grid edge under a large slip. Milestones: ▲ go-live (moves with slip) · ✕ Christmas · ! Bank holiday · ◆ drawn phase gate. Bar colours: SEGRO red · HCL dark blue · Azure mid blue · Third-party purple.
K3: Jul 26 | N3: Aug 26 | S3: Sep 26 | W3: Oct 26 | AA3: Nov 26 | AF3: Dec 26 | AJ3: Jan 27 | AN3: Feb 27 | AR3: Mar 27 | AW3: Apr 27 | BA3: May 27 | BF3: Jun 27 | BJ3: Jul 27 | BN3: Aug 27 | BS3: Sep 27
A4: Id | B4: Major line of work / technical step | C4: Side | D4: Status | E4: Findings | F4: Depends on | G4: Start wk | H4: Wks | I4: Live start | J4: Live end | K4: 1 | L4: 2 | M4: 3 | N4: 4 | O4: 5 | P4: 6 | Q4: 7 | R4: 8 | S4: 9 | T4: 10 | U4: 11 | V4: 12 | W4: 13 | X4: 14 | Y4: 15 | Z4: 16 | AA4: 17 | AB4: 18 | AC4: 19 | AD4: 20 | AE4: 21 | AF4: 22 | AG4: 23 | AH4: 24 | AI4: 25 | AJ4: 26 | AK4: 27 | AL4: 28 | AM4: 29 | AN4: 30 | AO4: 31 | AP4: 32 | AQ4: 33 | AR4: 34 | AS4: 35 | AT4: 36 | AU4: 37 | AV4: 38 | AW4: 39 | AX4: 40 | AY4: 41 | AZ4: 42 | BA4: 43 | BB4: 44 | BC4: 45 | BD4: 46 | BE4: 47 | BF4: 48 | BG4: 49 | BH4: 50 | BI4: 51 | BJ4: 52 | BK4: 53 | BL4: 54 | BM4: 55 | BN4: 56 | BO4: 57 | BP4: 58 | BQ4: 59 | BR4: 60 | BS4: 61 | BT4: Slip | BU4: Basis / source | BW4: =29+SlipWeeks -> 29
B5: Milestones | K5: =IF(K$4=$BW$4,"▲","") | L5: =IF(L$4=$BW$4,"▲","") | M5: =IF(M$4=$BW$4,"▲","") | N5: =IF(N$4=$BW$4,"▲","") | O5: =IF(O$4=$BW$4,"▲","◆") -> ◆ | P5: =IF(P$4=$BW$4,"▲","") | Q5: =IF(Q$4=$BW$4,"▲","") | R5: =IF(R$4=$BW$4,"▲","!") -> ! | S5: =IF(S$4=$BW$4,"▲","") | T5: =IF(T$4=$BW$4,"▲","") | U5: =IF(U$4=$BW$4,"▲","") | V5: =IF(V$4=$BW$4,"▲","") | W5: =IF(W$4=$BW$4,"▲","") | X5: =IF(X$4=$BW$4,"▲","") | Y5: =IF(Y$4=$BW$4,"▲","") | Z5: =IF(Z$4=$BW$4,"▲","") | ... AD5: =IF(AD$4=$BW$4,"▲","") | AE5: =IF(AE$4=$BW$4,"▲","◆") -> ◆ | AF5: =IF(AF$4=$BW$4,"▲","") | AG5: =IF(AG$4=$BW$4,"▲","") | AH5: =IF(AH$4=$BW$4,"▲","✕") -> ✕ | AI5: =IF(AI$4=$BW$4,"▲","◆") -> ◆ | AJ5: =IF(AJ$4=$BW$4,"▲","") | AK5: =IF(AK$4=$BW$4,"▲","") | AL5: =IF(AL$4=$BW$4,"▲","") | AM5: =IF(AM$4=$BW$4,"▲","") -> ▲ | AN5: =IF(AN$4=$BW$4,"▲","") | AO5: =IF(AO$4=$BW$4,"▲","") | AP5: =IF(AP$4=$BW$4,"▲","") | AQ5: =IF(AQ$4=$BW$4,"▲","") | ... BS5: =IF(BS$4=$BW$4,"▲","")
A6: G-P1-L1 | B6: Design & Plan (lane A) [P1-L1] | C6: SEGRO | D6: POAP-DRAWN | E6: F16 | G6: 1 | H6: 5 | I6: =MIN(61,IF(G6<=29,ROUND((G6-1)*(29+SlipWeeks)/29,0)+1,G6+SlipWeeks)) -> 1 | J6: =MIN(61,IF(G6+H6-1<=29,MAX(ROUND((G6+H6-1)*(29+SlipWeeks)/29,0),I6),G6+H6-1+SlipWeeks)) -> 5 | K6: =IF(AND(K$4>=$I6,K$4<=$J6),1,"") -> 1 | L6: =IF(AND(L$4>=$I6,L$4<=$J6),1,"") -> 1 | M6: =IF(AND(M$4>=$I6,M$4<=$J6),1,"") -> 1 | N6: =IF(AND(N$4>=$I6,N$4<=$J6),1,"") -> 1 | O6: =IF(AND(O$4>=$I6,O$4<=$J6),1,"") -> 1 | P6: =IF(AND(P$4>=$I6,P$4<=$J6),1,"") | Q6: =IF(AND(Q$4>=$I6,Q$4<=$J6),1,"") | R6: =IF(AND(R$4>=$I6,R$4<=$J6),1,"") | ... BS6: =IF(AND(BS$4>=$I6,BS$4<=$J6),1,"") | BT6: =IF(IF(G6+H6-1<=29,MAX(ROUND((G6+H6-1)*(29+SlipWeeks)/29,0),$I6),G6+H6-1+SlipWeeks)>61,"▶ clipped","") | BU6: Slide 3 lane A design bar is drawn: '5 weeks' bar x=1.98 w=2.54 = gantt_timeline P1 window weeks 1-5. Role/scope from spec_cost_model P1-L1: 'Solutions architect - workshop lead, HLD/LLD, target arch for EA, KDD papers (AKS v ARO, env count, cluster topology)', 1 FTE x 5 wk.
A7: G-P1-L1-s1 | B7: • Lead Arch Workshop Kick-off | C7: SEGRO | D7: DERIVED | G7: 1 | H7: 1 | I7: =MEDIAN($I$6,$J$6,$I$6+ROUND((G7-$G$6)/$H$6*($J$6-$I$6+1),0)) -> 1 | J7: =MEDIAN(I7,$J$6,$I$6+ROUND((G7+H7-$G$6)/$H$6*($J$6-$I$6+1),0)-1) -> 1 | K7: =IF(AND(K$4>=$I7,K$4<=$J7),1,"") -> 1 | L7: =IF(AND(L$4>=$I7,L$4<=$J7),1,"") | M7: =IF(AND(M$4>=$I7,M$4<=$J7),1,"") | N7: =IF(AND(N$4>=$I7,N$4<=$J7),1,"") | O7: =IF(AND(O$4>=$I7,O$4<=$J7),1,"") | P7: =IF(AND(P$4>=$I7,P$4<=$J7),1,"") | Q7: =IF(AND(Q$4>=$I7,Q$4<=$J7),1,"") | R7: =IF(AND(R$4>=$I7,R$4<=$J7),1,"") | ... BS7: =IF(AND(BS$4>=$I7,BS$4<=$J7),1,"") | BU7: Slide 3 chip 'Arch Workshop Kick-off' (x=1.40) is the first workshop in the drawn left-to-right stagger of the lane-A chain - earliest position, so week 1 at parent start.
A8: G-P1-L1-s2 | B8: • Lead Arch Workshop Sizing | C8: SEGRO | D8: DERIVED | F8: G-P1-L1-s1 | G8: 2 | H8: 1 | I8: =MEDIAN($I$6,$J$6,$I$6+ROUND((G8-$G$6)/$H$6*($J$6-$I$6+1),0)) -> 2 | J8: =MEDIAN(I8,$J$6,$I$6+ROUND((G8+H8-$G$6)/$H$6*($J$6-$I$6+1),0)-1) -> 2 | K8: =IF(AND(K$4>=$I8,K$4<=$J8),1,"") | L8: =IF(AND(L$4>=$I8,L$4<=$J8),1,"") -> 1 | M8: =IF(AND(M$4>=$I8,M$4<=$J8),1,"") | N8: =IF(AND(N$4>=$I8,N$4<=$J8),1,"") | O8: =IF(AND(O$4>=$I8,O$4<=$J8),1,"") | P8: =IF(AND(P$4>=$I8,P$4<=$J8),1,"") | Q8: =IF(AND(Q$4>=$I8,Q$4<=$J8),1,"") | R8: =IF(AND(R$4>=$I8,R$4<=$J8),1,"") | ... BS8: =IF(AND(BS$4>=$I8,BS$4<=$J8),1,"") | BU8: Slide 3 chip 'Arch Workshop Sizing' (x=1.65) is drawn second in the workshop stagger, immediately right of kick-off - next week slot.
A9: G-P1-L1-s3 | B9: • Draft KDD papers (AKS v ARO, env count, cluster topology) feeding the lane-B KDD decisions | C9: SEGRO | D9: ASSUMPTION | F9: G-P1-L1-s1 | G9: 2 | H9: 2 | I9: =MEDIAN($I$6,$J$6,$I$6+ROUND((G9-$G$6)/$H$6*($J$6-$I$6+1),0)) -> 2 | J9: =MEDIAN(I9,$J$6,$I$6+ROUND((G9+H9-$G$6)/$H$6*($J$6-$I$6+1),0)-1) -> 3 | K9: =IF(AND(K$4>=$I9,K$4<=$J9),1,"") | L9: =IF(AND(L$4>=$I9,L$4<=$J9),1,"") -> 1 | M9: =IF(AND(M$4>=$I9,M$4<=$J9),1,"") -> 1 | N9: =IF(AND(N$4>=$I9,N$4<=$J9),1,"") | O9: =IF(AND(O$4>=$I9,O$4<=$J9),1,"") | P9: =IF(AND(P$4>=$I9,P$4<=$J9),1,"") | Q9: =IF(AND(Q$4>=$I9,Q$4<=$J9),1,"") | R9: =IF(AND(R$4>=$I9,R$4<=$J9),1,"") | ... BS9: =IF(AND(BS$4>=$I9,BS$4<=$J9),1,"") | BU9: Text from spec_cost_model P1-L1 desc: 'KDD papers (AKS v ARO, env count, cluster topology)'. Position is judgement: drafting must follow the kick-off/sizing workshops and precede the lane-B 'KDDs documented / agreed' close-out - no drawn bar for the drafting itself.
A10: G-P1-L1-s4 | B10: • Produce High Level Design | C10: SEGRO | D10: ASSUMPTION | F10: G-P1-L1-s2 | G10: 3 | H10: 2 | I10: =MEDIAN($I$6,$J$6,$I$6+ROUND((G10-$G$6)/$H$6*($J$6-$I$6+1),0)) -> 3 | J10: =MEDIAN(I10,$J$6,$I$6+ROUND((G10+H10-$G$6)/$H$6*($J$6-$I$6+1),0)-1) -> 4 | K10: =IF(AND(K$4>=$I10,K$4<=$J10),1,"") | L10: =IF(AND(L$4>=$I10,L$4<=$J10),1,"") | M10: =IF(AND(M$4>=$I10,M$4<=$J10),1,"") -> 1 | N10: =IF(AND(N$4>=$I10,N$4<=$J10),1,"") -> 1 | O10: =IF(AND(O$4>=$I10,O$4<=$J10),1,"") | P10: =IF(AND(P$4>=$I10,P$4<=$J10),1,"") | Q10: =IF(AND(Q$4>=$I10,Q$4<=$J10),1,"") | R10: =IF(AND(R$4>=$I10,R$4<=$J10),1,"") | ... BS10: =IF(AND(BS$4>=$I10,BS$4<=$J10),1,"") | BU10: Slide 5 named doc 'High Level Design'. Position is judgement: mid-phase, after the sizing and cyber workshops provide inputs; slide gives no per-document dates.
A11: G-P1-L1-s5 | B11: • Target Arch for EA (consuming platform engineer's physical infrastructure diagrams) | C11: SEGRO | D11: DERIVED | F11: G-P1-L1-s4 | G11: 4 | H11: 1 | I11: =MEDIAN($I$6,$J$6,$I$6+ROUND((G11-$G$6)/$H$6*($J$6-$I$6+1),0)) -> 4 | J11: =MEDIAN(I11,$J$6,$I$6+ROUND((G11+H11-$G$6)/$H$6*($J$6-$I$6+1),0)-1) -> 4 | K11: =IF(AND(K$4>=$I11,K$4<=$J11),1,"") | L11: =IF(AND(L$4>=$I11,L$4<=$J11),1,"") | M11: =IF(AND(M$4>=$I11,M$4<=$J11),1,"") | N11: =IF(AND(N$4>=$I11,N$4<=$J11),1,"") -> 1 | O11: =IF(AND(O$4>=$I11,O$4<=$J11),1,"") | P11: =IF(AND(P$4>=$I11,P$4<=$J11),1,"") | Q11: =IF(AND(Q$4>=$I11,Q$4<=$J11),1,"") | R11: =IF(AND(R$4>=$I11,R$4<=$J11),1,"") | ... BS11: =IF(AND(BS$4>=$I11,BS$4<=$J11),1,"") | BU11: Slide 3 chip 'Physical infrastructure diagrams and Target Arch for EA' (x=3.07) is drawn last in the lane-A stagger, late in the design bar - week 4 position follows from the drawn order.
A12: G-P1-L1-s6 | B12: • Finalise Low Level Design for Enterprise Arch; KDDs documented / agreed | C12: SEGRO | D12: ASSUMPTION | F12: G-P1-L1-s3, G-P1-L1-s4 | G12: 4 | H12: 2 | I12: =MEDIAN($I$6,$J$6,$I$6+ROUND((G12-$G$6)/$H$6*($J$6-$I$6+1),0)) -> 4 | J12: =MEDIAN(I12,$J$6,$I$6+ROUND((G12+H12-$G$6)/$H$6*($J$6-$I$6+1),0)-1) -> 5 | K12: =IF(AND(K$4>=$I12,K$4<=$J12),1,"") | L12: =IF(AND(L$4>=$I12,L$4<=$J12),1,"") | M12: =IF(AND(M$4>=$I12,M$4<=$J12),1,"") | N12: =IF(AND(N$4>=$I12,N$4<=$J12),1,"") -> 1 | O12: =IF(AND(O$4>=$I12,O$4<=$J12),1,"") -> 1 | P12: =IF(AND(P$4>=$I12,P$4<=$J12),1,"") | Q12: =IF(AND(Q$4>=$I12,Q$4<=$J12),1,"") | R12: =IF(AND(R$4>=$I12,R$4<=$J12),1,"") | ... BS12: =IF(AND(BS$4>=$I12,BS$4<=$J12),1,"") | BU12: Slide 5 named docs 'Low Level Design for Enterprise Arch' and 'KDDs documented / agreed'. Position is judgement: closing deliverables in the final two weeks before the slide-3 'Design phase complete' marker; no per-document dates drawn.
A14: G-P1-L2 | B14: Design & Plan (lane A) [P1-L2] | C14: SEGRO | D14: POAP-DRAWN | E14: F16, F14 | G14: 1 | H14: 5 | I14: =MIN(61,IF(G14<=29,ROUND((G14-1)*(29+SlipWeeks)/29,0)+1,G14+SlipWeeks)) -> 1 | J14: =MIN(61,IF(G14+H14-1<=29,MAX(ROUND((G14+H14-1)*(29+SlipWeeks)/29,0),I14),G14+H14-1+SlipWeeks)) -> 5 | K14: =IF(AND(K$4>=$I14,K$4<=$J14),1,"") -> 1 | L14: =IF(AND(L$4>=$I14,L$4<=$J14),1,"") -> 1 | M14: =IF(AND(M$4>=$I14,M$4<=$J14),1,"") -> 1 | N14: =IF(AND(N$4>=$I14,N$4<=$J14),1,"") -> 1 | O14: =IF(AND(O$4>=$I14,O$4<=$J14),1,"") -> 1 | P14: =IF(AND(P$4>=$I14,P$4<=$J14),1,"") | Q14: =IF(AND(Q$4>=$I14,Q$4<=$J14),1,"") | R14: =IF(AND(R$4>=$I14,R$4<=$J14),1,"") | ... BS14: =IF(AND(BS$4>=$I14,BS$4<=$J14),1,"") | BT14: =IF(IF(G14+H14-1<=29,MAX(ROUND((G14+H14-1)*(29+SlipWeeks)/29,0),$I14),G14+H14-1+SlipWeeks)>61,"▶ clipped","") | BU14: Window = drawn slide 3 '5 weeks' design bar (x=1.98 w=2.54) = weeks 1-5. Role/scope from spec_cost_model P1-L2: 'Platform engineer - sizing workshop, physical infrastructure diagrams, physical sizing of infrastructure', 0.6 FTE.
A15: G-P1-L2-s1 | B15: • Attend Arch Workshop Kick-off; assemble estate sizing inputs | C15: SEGRO | D15: DERIVED | G15: 1 | H15: 1 | I15: =MEDIAN($I$14,$J$14,$I$14+ROUND((G15-$G$14)/$H$14*($J$14-$I$14+1),0)) -> 1 | J15: =MEDIAN(I15,$J$14,$I$14+ROUND((G15+H15-$G$14)/$H$14*($J$14-$I$14+1),0)-1) -> 1 | K15: =IF(AND(K$4>=$I15,K$4<=$J15),1,"") -> 1 | L15: =IF(AND(L$4>=$I15,L$4<=$J15),1,"") | M15: =IF(AND(M$4>=$I15,M$4<=$J15),1,"") | N15: =IF(AND(N$4>=$I15,N$4<=$J15),1,"") | O15: =IF(AND(O$4>=$I15,O$4<=$J15),1,"") | P15: =IF(AND(P$4>=$I15,P$4<=$J15),1,"") | Q15: =IF(AND(Q$4>=$I15,Q$4<=$J15),1,"") | R15: =IF(AND(R$4>=$I15,R$4<=$J15),1,"") | ... BS15: =IF(AND(BS$4>=$I15,BS$4<=$J15),1,"") | BU15: Slide 3 chip 'Arch Workshop Kick-off' (x=1.40), first in the drawn stagger - week 1 at parent start; sizing-input scope from spec_cost_model P1-L2 desc 'sizing workshop'.
A16: G-P1-L2-s2 | B16: • Run Arch Workshop Sizing (the workshop the build phase is 'To be validated' against) | C16: SEGRO | D16: DERIVED | F16: G-P1-L2-s1 | G16: 2 | H16: 1 | I16: =MEDIAN($I$14,$J$14,$I$14+ROUND((G16-$G$14)/$H$14*($J$14-$I$14+1),0)) -> 2 | J16: =MEDIAN(I16,$J$14,$I$14+ROUND((G16+H16-$G$14)/$H$14*($J$14-$I$14+1),0)-1) -> 2 | K16: =IF(AND(K$4>=$I16,K$4<=$J16),1,"") | L16: =IF(AND(L$4>=$I16,L$4<=$J16),1,"") -> 1 | M16: =IF(AND(M$4>=$I16,M$4<=$J16),1,"") | N16: =IF(AND(N$4>=$I16,N$4<=$J16),1,"") | O16: =IF(AND(O$4>=$I16,O$4<=$J16),1,"") | P16: =IF(AND(P$4>=$I16,P$4<=$J16),1,"") | Q16: =IF(AND(Q$4>=$I16,Q$4<=$J16),1,"") | R16: =IF(AND(R$4>=$I16,R$4<=$J16),1,"") | ... BS16: =IF(AND(BS$4>=$I16,BS$4<=$J16),1,"") | BU16: Slide 3 chip 'Arch Workshop Sizing' (x=1.65), second in the drawn stagger. Slide 3 build annotation 'To be validated based on Arch workshop' (x=6.85) hangs on this workshop's output (F14).
A17: G-P1-L2-s3 | B17: • Physical sizing of infrastructure | C17: SEGRO | D17: ASSUMPTION | F17: G-P1-L2-s2 | G17: 3 | H17: 2 | I17: =MEDIAN($I$14,$J$14,$I$14+ROUND((G17-$G$14)/$H$14*($J$14-$I$14+1),0)) -> 3 | J17: =MEDIAN(I17,$J$14,$I$14+ROUND((G17+H17-$G$14)/$H$14*($J$14-$I$14+1),0)-1) -> 4 | K17: =IF(AND(K$4>=$I17,K$4<=$J17),1,"") | L17: =IF(AND(L$4>=$I17,L$4<=$J17),1,"") | M17: =IF(AND(M$4>=$I17,M$4<=$J17),1,"") -> 1 | N17: =IF(AND(N$4>=$I17,N$4<=$J17),1,"") -> 1 | O17: =IF(AND(O$4>=$I17,O$4<=$J17),1,"") | P17: =IF(AND(P$4>=$I17,P$4<=$J17),1,"") | Q17: =IF(AND(Q$4>=$I17,Q$4<=$J17),1,"") | R17: =IF(AND(R$4>=$I17,R$4<=$J17),1,"") | ... BS17: =IF(AND(BS$4>=$I17,BS$4<=$J17),1,"") | BU17: Slide 5 named doc 'Physical sizing of infrastructure'. Position is judgement: follows the sizing workshop; no drawn bar for the document itself.
A18: G-P1-L2-s4 | B18: • Physical Low Level Technical Arch Diagrams / physical infrastructure diagrams | C18: SEGRO | D18: DERIVED | F18: G-P1-L2-s3 | G18: 4 | H18: 2 | I18: =MEDIAN($I$14,$J$14,$I$14+ROUND((G18-$G$14)/$H$14*($J$14-$I$14+1),0)) -> 4 | J18: =MEDIAN(I18,$J$14,$I$14+ROUND((G18+H18-$G$14)/$H$14*($J$14-$I$14+1),0)-1) -> 5 | K18: =IF(AND(K$4>=$I18,K$4<=$J18),1,"") | L18: =IF(AND(L$4>=$I18,L$4<=$J18),1,"") | M18: =IF(AND(M$4>=$I18,M$4<=$J18),1,"") | N18: =IF(AND(N$4>=$I18,N$4<=$J18),1,"") -> 1 | O18: =IF(AND(O$4>=$I18,O$4<=$J18),1,"") -> 1 | P18: =IF(AND(P$4>=$I18,P$4<=$J18),1,"") | Q18: =IF(AND(Q$4>=$I18,Q$4<=$J18),1,"") | R18: =IF(AND(R$4>=$I18,R$4<=$J18),1,"") | ... BS18: =IF(AND(BS$4>=$I18,BS$4<=$J18),1,"") | BU18: Slide 5 named doc 'Physical Low Level Technical Arch Diagrams'; slide 3 chip 'Physical infrastructure diagrams and Target Arch for EA' (x=3.07) is drawn last in the lane-A stagger - late-phase position follows from the drawn order.
A20: G-P1-L3 | B20: Design & Plan (lane A) [P1-L3] | C20: SEGRO | D20: POAP-DRAWN | E20: F16 | G20: 1 | H20: 5 | I20: =MIN(61,IF(G20<=29,ROUND((G20-1)*(29+SlipWeeks)/29,0)+1,G20+SlipWeeks)) -> 1 | J20: =MIN(61,IF(G20+H20-1<=29,MAX(ROUND((G20+H20-1)*(29+SlipWeeks)/29,0),I20),G20+H20-1+SlipWeeks)) -> 5 | K20: =IF(AND(K$4>=$I20,K$4<=$J20),1,"") -> 1 | L20: =IF(AND(L$4>=$I20,L$4<=$J20),1,"") -> 1 | M20: =IF(AND(M$4>=$I20,M$4<=$J20),1,"") -> 1 | N20: =IF(AND(N$4>=$I20,N$4<=$J20),1,"") -> 1 | O20: =IF(AND(O$4>=$I20,O$4<=$J20),1,"") -> 1 | P20: =IF(AND(P$4>=$I20,P$4<=$J20),1,"") | Q20: =IF(AND(Q$4>=$I20,Q$4<=$J20),1,"") | R20: =IF(AND(R$4>=$I20,R$4<=$J20),1,"") | ... BS20: =IF(AND(BS$4>=$I20,BS$4<=$J20),1,"") | BT20: =IF(IF(G20+H20-1<=29,MAX(ROUND((G20+H20-1)*(29+SlipWeeks)/29,0),$I20),G20+H20-1+SlipWeeks)>61,"▶ clipped","") | BU20: Window = drawn slide 3 '5 weeks' design bar = weeks 1-5. Role/scope from spec_cost_model P1-L3: 'Cloud security - Cyber Sec Workshop, cyber security impact analysis + diagrams', 0.4 FTE; IAM workshop/design mapped here as the security-owning role.
A21: G-P1-L3-s1 | B21: • Prepare Cyber Sec Workshop inputs (SEGRO security principles, threat context) | C21: SEGRO | D21: ASSUMPTION | G21: 1 | H21: 1 | I21: =MEDIAN($I$20,$J$20,$I$20+ROUND((G21-$G$20)/$H$20*($J$20-$I$20+1),0)) -> 1 | J21: =MEDIAN(I21,$J$20,$I$20+ROUND((G21+H21-$G$20)/$H$20*($J$20-$I$20+1),0)-1) -> 1 | K21: =IF(AND(K$4>=$I21,K$4<=$J21),1,"") -> 1 | L21: =IF(AND(L$4>=$I21,L$4<=$J21),1,"") | M21: =IF(AND(M$4>=$I21,M$4<=$J21),1,"") | N21: =IF(AND(N$4>=$I21,N$4<=$J21),1,"") | O21: =IF(AND(O$4>=$I21,O$4<=$J21),1,"") | P21: =IF(AND(P$4>=$I21,P$4<=$J21),1,"") | Q21: =IF(AND(Q$4>=$I21,Q$4<=$J21),1,"") | R21: =IF(AND(R$4>=$I21,R$4<=$J21),1,"") | ... BS21: =IF(AND(BS$4>=$I21,BS$4<=$J21),1,"") | BU21: Workshop named on slide 3 ('Cyber Sec Workshop'); preparation step and its week-1 position are judgement - only the workshop chip itself is drawn.
A22: G-P1-L3-s2 | B22: • Run Cyber Sec Workshop | C22: SEGRO | D22: DERIVED | F22: G-P1-L3-s1 | G22: 2 | H22: 1 | I22: =MEDIAN($I$20,$J$20,$I$20+ROUND((G22-$G$20)/$H$20*($J$20-$I$20+1),0)) -> 2 | J22: =MEDIAN(I22,$J$20,$I$20+ROUND((G22+H22-$G$20)/$H$20*($J$20-$I$20+1),0)-1) -> 2 | K22: =IF(AND(K$4>=$I22,K$4<=$J22),1,"") | L22: =IF(AND(L$4>=$I22,L$4<=$J22),1,"") -> 1 | M22: =IF(AND(M$4>=$I22,M$4<=$J22),1,"") | N22: =IF(AND(N$4>=$I22,N$4<=$J22),1,"") | O22: =IF(AND(O$4>=$I22,O$4<=$J22),1,"") | P22: =IF(AND(P$4>=$I22,P$4<=$J22),1,"") | Q22: =IF(AND(Q$4>=$I22,Q$4<=$J22),1,"") | R22: =IF(AND(R$4>=$I22,R$4<=$J22),1,"") | ... BS22: =IF(AND(BS$4>=$I22,BS$4<=$J22),1,"") | BU22: Slide 3 chip 'Cyber Sec Workshop' (x=1.90), third in the drawn left-to-right workshop stagger - early-mid phase position follows from the drawn order.
A23: G-P1-L3-s3 | B23: • Run Identity Access Mgmt Workshop | C23: SEGRO | D23: DERIVED | F23: G-P1-L3-s2 | G23: 3 | H23: 1 | I23: =MEDIAN($I$20,$J$20,$I$20+ROUND((G23-$G$20)/$H$20*($J$20-$I$20+1),0)) -> 3 | J23: =MEDIAN(I23,$J$20,$I$20+ROUND((G23+H23-$G$20)/$H$20*($J$20-$I$20+1),0)-1) -> 3 | K23: =IF(AND(K$4>=$I23,K$4<=$J23),1,"") | L23: =IF(AND(L$4>=$I23,L$4<=$J23),1,"") | M23: =IF(AND(M$4>=$I23,M$4<=$J23),1,"") -> 1 | N23: =IF(AND(N$4>=$I23,N$4<=$J23),1,"") | O23: =IF(AND(O$4>=$I23,O$4<=$J23),1,"") | P23: =IF(AND(P$4>=$I23,P$4<=$J23),1,"") | Q23: =IF(AND(Q$4>=$I23,Q$4<=$J23),1,"") | R23: =IF(AND(R$4>=$I23,R$4<=$J23),1,"") | ... BS23: =IF(AND(BS$4>=$I23,BS$4<=$J23),1,"") | BU23: Slide 3 chip 'Identity Access Mgmt Workshop' (x=2.01), fourth in the drawn stagger, right of the Cyber Sec Workshop chip.
A24: G-P1-L3-s4 | B24: • Cyber security impact analysis | C24: SEGRO | D24: ASSUMPTION | F24: G-P1-L3-s2 | G24: 3 | H24: 2 | I24: =MEDIAN($I$20,$J$20,$I$20+ROUND((G24-$G$20)/$H$20*($J$20-$I$20+1),0)) -> 3 | J24: =MEDIAN(I24,$J$20,$I$20+ROUND((G24+H24-$G$20)/$H$20*($J$20-$I$20+1),0)-1) -> 4 | K24: =IF(AND(K$4>=$I24,K$4<=$J24),1,"") | L24: =IF(AND(L$4>=$I24,L$4<=$J24),1,"") | M24: =IF(AND(M$4>=$I24,M$4<=$J24),1,"") -> 1 | N24: =IF(AND(N$4>=$I24,N$4<=$J24),1,"") -> 1 | O24: =IF(AND(O$4>=$I24,O$4<=$J24),1,"") | P24: =IF(AND(P$4>=$I24,P$4<=$J24),1,"") | Q24: =IF(AND(Q$4>=$I24,Q$4<=$J24),1,"") | R24: =IF(AND(R$4>=$I24,R$4<=$J24),1,"") | ... BS24: =IF(AND(BS$4>=$I24,BS$4<=$J24),1,"") | BU24: Slide 5 named doc 'Cyber security impact analysis'. Position is judgement: follows the Cyber Sec Workshop; no drawn bar for the document.
A25: G-P1-L3-s5 | B25: • Cyber security diagrams | C25: SEGRO | D25: ASSUMPTION | F25: G-P1-L3-s4 | G25: 4 | H25: 2 | I25: =MEDIAN($I$20,$J$20,$I$20+ROUND((G25-$G$20)/$H$20*($J$20-$I$20+1),0)) -> 4 | J25: =MEDIAN(I25,$J$20,$I$20+ROUND((G25+H25-$G$20)/$H$20*($J$20-$I$20+1),0)-1) -> 5 | K25: =IF(AND(K$4>=$I25,K$4<=$J25),1,"") | L25: =IF(AND(L$4>=$I25,L$4<=$J25),1,"") | M25: =IF(AND(M$4>=$I25,M$4<=$J25),1,"") | N25: =IF(AND(N$4>=$I25,N$4<=$J25),1,"") -> 1 | O25: =IF(AND(O$4>=$I25,O$4<=$J25),1,"") -> 1 | P25: =IF(AND(P$4>=$I25,P$4<=$J25),1,"") | Q25: =IF(AND(Q$4>=$I25,Q$4<=$J25),1,"") | R25: =IF(AND(R$4>=$I25,R$4<=$J25),1,"") | ... BS25: =IF(AND(BS$4>=$I25,BS$4<=$J25),1,"") | BU25: Slide 5 named doc 'Cyber security diagrams'. Position is judgement: diagrams follow the impact analysis in the phase tail.
A26: G-P1-L3-s6 | B26: • Identity & access management design | C26: SEGRO | D26: ASSUMPTION | F26: G-P1-L3-s3 | G26: 4 | H26: 2 | I26: =MEDIAN($I$20,$J$20,$I$20+ROUND((G26-$G$20)/$H$20*($J$20-$I$20+1),0)) -> 4 | J26: =MEDIAN(I26,$J$20,$I$20+ROUND((G26+H26-$G$20)/$H$20*($J$20-$I$20+1),0)-1) -> 5 | K26: =IF(AND(K$4>=$I26,K$4<=$J26),1,"") | L26: =IF(AND(L$4>=$I26,L$4<=$J26),1,"") | M26: =IF(AND(M$4>=$I26,M$4<=$J26),1,"") | N26: =IF(AND(N$4>=$I26,N$4<=$J26),1,"") -> 1 | O26: =IF(AND(O$4>=$I26,O$4<=$J26),1,"") -> 1 | P26: =IF(AND(P$4>=$I26,P$4<=$J26),1,"") | Q26: =IF(AND(Q$4>=$I26,Q$4<=$J26),1,"") | R26: =IF(AND(R$4>=$I26,R$4<=$J26),1,"") | ... BS26: =IF(AND(BS$4>=$I26,BS$4<=$J26),1,"") | BU26: Slide 5 named doc 'Identity & access management design'. Position is judgement: follows the IAM workshop; closes with the phase.
A28: G-P1-L4 | B28: Design & Plan (lane A) [P1-L4] | C28: SEGRO | D28: POAP-DRAWN | E28: F16 | G28: 1 | H28: 5 | I28: =MIN(61,IF(G28<=29,ROUND((G28-1)*(29+SlipWeeks)/29,0)+1,G28+SlipWeeks)) -> 1 | J28: =MIN(61,IF(G28+H28-1<=29,MAX(ROUND((G28+H28-1)*(29+SlipWeeks)/29,0),I28),G28+H28-1+SlipWeeks)) -> 5 | K28: =IF(AND(K$4>=$I28,K$4<=$J28),1,"") -> 1 | L28: =IF(AND(L$4>=$I28,L$4<=$J28),1,"") -> 1 | M28: =IF(AND(M$4>=$I28,M$4<=$J28),1,"") -> 1 | N28: =IF(AND(N$4>=$I28,N$4<=$J28),1,"") -> 1 | O28: =IF(AND(O$4>=$I28,O$4<=$J28),1,"") -> 1 | P28: =IF(AND(P$4>=$I28,P$4<=$J28),1,"") | Q28: =IF(AND(Q$4>=$I28,Q$4<=$J28),1,"") | R28: =IF(AND(R$4>=$I28,R$4<=$J28),1,"") | ... BS28: =IF(AND(BS$4>=$I28,BS$4<=$J28),1,"") | BT28: =IF(IF(G28+H28-1<=29,MAX(ROUND((G28+H28-1)*(29+SlipWeeks)/29,0),$I28),G28+H28-1+SlipWeeks)>61,"▶ clipped","") | BU28: Window = drawn slide 3 '5 weeks' design bar = weeks 1-5. Role/scope from spec_cost_model P1-L4: 'Data engineer - Data Mgmt Workshop, data flow design, data governance principles input', 0.4 FTE.
A29: G-P1-L4-s1 | B29: • Prepare Data Mgmt Workshop inputs (data landscape, governance principles) | C29: SEGRO | D29: ASSUMPTION | G29: 1 | H29: 2 | I29: =MEDIAN($I$28,$J$28,$I$28+ROUND((G29-$G$28)/$H$28*($J$28-$I$28+1),0)) -> 1 | J29: =MEDIAN(I29,$J$28,$I$28+ROUND((G29+H29-$G$28)/$H$28*($J$28-$I$28+1),0)-1) -> 2 | K29: =IF(AND(K$4>=$I29,K$4<=$J29),1,"") -> 1 | L29: =IF(AND(L$4>=$I29,L$4<=$J29),1,"") -> 1 | M29: =IF(AND(M$4>=$I29,M$4<=$J29),1,"") | N29: =IF(AND(N$4>=$I29,N$4<=$J29),1,"") | O29: =IF(AND(O$4>=$I29,O$4<=$J29),1,"") | P29: =IF(AND(P$4>=$I29,P$4<=$J29),1,"") | Q29: =IF(AND(Q$4>=$I29,Q$4<=$J29),1,"") | R29: =IF(AND(R$4>=$I29,R$4<=$J29),1,"") | ... BS29: =IF(AND(BS$4>=$I29,BS$4<=$J29),1,"") | BU29: Text from spec_cost_model P1-L4 desc 'data governance principles input' and the slide-3 workshop name; preparation step and its position are judgement - only the workshop chip is drawn.
A30: G-P1-L4-s2 | B30: • Run Data Mgmt Workshop | C30: SEGRO | D30: DERIVED | F30: G-P1-L4-s1 | G30: 3 | H30: 1 | I30: =MEDIAN($I$28,$J$28,$I$28+ROUND((G30-$G$28)/$H$28*($J$28-$I$28+1),0)) -> 3 | J30: =MEDIAN(I30,$J$28,$I$28+ROUND((G30+H30-$G$28)/$H$28*($J$28-$I$28+1),0)-1) -> 3 | K30: =IF(AND(K$4>=$I30,K$4<=$J30),1,"") | L30: =IF(AND(L$4>=$I30,L$4<=$J30),1,"") | M30: =IF(AND(M$4>=$I30,M$4<=$J30),1,"") -> 1 | N30: =IF(AND(N$4>=$I30,N$4<=$J30),1,"") | O30: =IF(AND(O$4>=$I30,O$4<=$J30),1,"") | P30: =IF(AND(P$4>=$I30,P$4<=$J30),1,"") | Q30: =IF(AND(Q$4>=$I30,Q$4<=$J30),1,"") | R30: =IF(AND(R$4>=$I30,R$4<=$J30),1,"") | ... BS30: =IF(AND(BS$4>=$I30,BS$4<=$J30),1,"") | BU30: Slide 3 chip 'Data Mgmt Workshop' (x=2.31), fifth and last workshop in the drawn left-to-right stagger - mid-phase position follows from the drawn order.
A31: G-P1-L4-s3 | B31: • Data flow design | C31: SEGRO | D31: ASSUMPTION | F31: G-P1-L4-s2 | G31: 4 | H31: 2 | I31: =MEDIAN($I$28,$J$28,$I$28+ROUND((G31-$G$28)/$H$28*($J$28-$I$28+1),0)) -> 4 | J31: =MEDIAN(I31,$J$28,$I$28+ROUND((G31+H31-$G$28)/$H$28*($J$28-$I$28+1),0)-1) -> 5 | K31: =IF(AND(K$4>=$I31,K$4<=$J31),1,"") | L31: =IF(AND(L$4>=$I31,L$4<=$J31),1,"") | M31: =IF(AND(M$4>=$I31,M$4<=$J31),1,"") | N31: =IF(AND(N$4>=$I31,N$4<=$J31),1,"") -> 1 | O31: =IF(AND(O$4>=$I31,O$4<=$J31),1,"") -> 1 | P31: =IF(AND(P$4>=$I31,P$4<=$J31),1,"") | Q31: =IF(AND(Q$4>=$I31,Q$4<=$J31),1,"") | R31: =IF(AND(R$4>=$I31,R$4<=$J31),1,"") | ... BS31: =IF(AND(BS$4>=$I31,BS$4<=$J31),1,"") | BU31: Slide 5 named doc 'Data flow design'. Position is judgement: follows the Data Mgmt Workshop; no drawn bar for the document.
A32: G-P1-L4-s4 | B32: • Data governance principles input handed to the build-phase Data Mgmt & Governance workstream | C32: SEGRO | D32: ASSUMPTION | F32: G-P1-L4-s2 | G32: 4 | H32: 2 | I32: =MEDIAN($I$28,$J$28,$I$28+ROUND((G32-$G$28)/$H$28*($J$28-$I$28+1),0)) -> 4 | J32: =MEDIAN(I32,$J$28,$I$28+ROUND((G32+H32-$G$28)/$H$28*($J$28-$I$28+1),0)-1) -> 5 | K32: =IF(AND(K$4>=$I32,K$4<=$J32),1,"") | L32: =IF(AND(L$4>=$I32,L$4<=$J32),1,"") | M32: =IF(AND(M$4>=$I32,M$4<=$J32),1,"") | N32: =IF(AND(N$4>=$I32,N$4<=$J32),1,"") -> 1 | O32: =IF(AND(O$4>=$I32,O$4<=$J32),1,"") -> 1 | P32: =IF(AND(P$4>=$I32,P$4<=$J32),1,"") | Q32: =IF(AND(Q$4>=$I32,Q$4<=$J32),1,"") | R32: =IF(AND(R$4>=$I32,R$4<=$J32),1,"") | ... BS32: =IF(AND(BS$4>=$I32,BS$4<=$J32),1,"") | BU32: Text from spec_cost_model P1-L4 desc 'data governance principles input' (the downstream stream is slide 3 build item 6 'Data Mgmt and Governance Principles'). Handover position at phase tail is judgement.
A34: G-P1-L5 | B34: Design & Plan (lane A) [P1-L5] | C34: SEGRO | D34: POAP-DRAWN | E34: F16 | G34: 1 | H34: 5 | I34: =MIN(61,IF(G34<=29,ROUND((G34-1)*(29+SlipWeeks)/29,0)+1,G34+SlipWeeks)) -> 1 | J34: =MIN(61,IF(G34+H34-1<=29,MAX(ROUND((G34+H34-1)*(29+SlipWeeks)/29,0),I34),G34+H34-1+SlipWeeks)) -> 5 | K34: =IF(AND(K$4>=$I34,K$4<=$J34),1,"") -> 1 | L34: =IF(AND(L$4>=$I34,L$4<=$J34),1,"") -> 1 | M34: =IF(AND(M$4>=$I34,M$4<=$J34),1,"") -> 1 | N34: =IF(AND(N$4>=$I34,N$4<=$J34),1,"") -> 1 | O34: =IF(AND(O$4>=$I34,O$4<=$J34),1,"") -> 1 | P34: =IF(AND(P$4>=$I34,P$4<=$J34),1,"") | Q34: =IF(AND(Q$4>=$I34,Q$4<=$J34),1,"") | R34: =IF(AND(R$4>=$I34,R$4<=$J34),1,"") | ... BS34: =IF(AND(BS$4>=$I34,BS$4<=$J34),1,"") | BT34: =IF(IF(G34+H34-1<=29,MAX(ROUND((G34+H34-1)*(29+SlipWeeks)/29,0),$I34),G34+H34-1+SlipWeeks)>61,"▶ clipped","") | BU34: Window = drawn slide 3 '5 weeks' design bar = weeks 1-5. Role/scope from spec_cost_model P1-L5: 'Business analyst - Use case scope for Release 1 Agreed, KDD documentation, DRG/ARG approval pack', 0.4 FTE.
A35: G-P1-L5-s1 | B35: • Use case scoping for Release 1, closing with 'Use case scope for Release 1 Agreed' | C35: SEGRO | D35: DERIVED | G35: 1 | H35: 2 | I35: =MEDIAN($I$34,$J$34,$I$34+ROUND((G35-$G$34)/$H$34*($J$34-$I$34+1),0)) -> 1 | J35: =MEDIAN(I35,$J$34,$I$34+ROUND((G35+H35-$G$34)/$H$34*($J$34-$I$34+1),0)-1) -> 2 | K35: =IF(AND(K$4>=$I35,K$4<=$J35),1,"") -> 1 | L35: =IF(AND(L$4>=$I35,L$4<=$J35),1,"") -> 1 | M35: =IF(AND(M$4>=$I35,M$4<=$J35),1,"") | N35: =IF(AND(N$4>=$I35,N$4<=$J35),1,"") | O35: =IF(AND(O$4>=$I35,O$4<=$J35),1,"") | P35: =IF(AND(P$4>=$I35,P$4<=$J35),1,"") | Q35: =IF(AND(Q$4>=$I35,Q$4<=$J35),1,"") | R35: =IF(AND(R$4>=$I35,R$4<=$J35),1,"") | ... BS35: =IF(AND(BS$4>=$I35,BS$4<=$J35),1,"") | BU35: Slide 3 chip 'Use case scope for Release 1 Agreed' (x=1.95) is drawn at the very start of the design bar (bar starts x=1.98) - early position follows from the drawing.
A36: G-P1-L5-s2 | B36: • Business context input to the workshop chain (sizing, cyber, IAM, data) | C36: SEGRO | D36: ASSUMPTION | F36: G-P1-L5-s1 | G36: 2 | H36: 2 | I36: =MEDIAN($I$34,$J$34,$I$34+ROUND((G36-$G$34)/$H$34*($J$34-$I$34+1),0)) -> 2 | J36: =MEDIAN(I36,$J$34,$I$34+ROUND((G36+H36-$G$34)/$H$34*($J$34-$I$34+1),0)-1) -> 3 | K36: =IF(AND(K$4>=$I36,K$4<=$J36),1,"") | L36: =IF(AND(L$4>=$I36,L$4<=$J36),1,"") -> 1 | M36: =IF(AND(M$4>=$I36,M$4<=$J36),1,"") -> 1 | N36: =IF(AND(N$4>=$I36,N$4<=$J36),1,"") | O36: =IF(AND(O$4>=$I36,O$4<=$J36),1,"") | P36: =IF(AND(P$4>=$I36,P$4<=$J36),1,"") | Q36: =IF(AND(Q$4>=$I36,Q$4<=$J36),1,"") | R36: =IF(AND(R$4>=$I36,R$4<=$J36),1,"") | ... BS36: =IF(AND(BS$4>=$I36,BS$4<=$J36),1,"") | BU36: Workshops named on slide 3 ('Arch Workshop Sizing', 'Cyber Sec Workshop', 'Identity Access Mgmt Workshop', 'Data Mgmt Workshop'); BA attendance and its weeks-2-3 position are judgement.
A37: G-P1-L5-s3 | B37: • KDD documentation | C37: SEGRO | D37: ASSUMPTION | F37: G-P1-L5-s2 | G37: 3 | H37: 2 | I37: =MEDIAN($I$34,$J$34,$I$34+ROUND((G37-$G$34)/$H$34*($J$34-$I$34+1),0)) -> 3 | J37: =MEDIAN(I37,$J$34,$I$34+ROUND((G37+H37-$G$34)/$H$34*($J$34-$I$34+1),0)-1) -> 4 | K37: =IF(AND(K$4>=$I37,K$4<=$J37),1,"") | L37: =IF(AND(L$4>=$I37,L$4<=$J37),1,"") | M37: =IF(AND(M$4>=$I37,M$4<=$J37),1,"") -> 1 | N37: =IF(AND(N$4>=$I37,N$4<=$J37),1,"") -> 1 | O37: =IF(AND(O$4>=$I37,O$4<=$J37),1,"") | P37: =IF(AND(P$4>=$I37,P$4<=$J37),1,"") | Q37: =IF(AND(Q$4>=$I37,Q$4<=$J37),1,"") | R37: =IF(AND(R$4>=$I37,R$4<=$J37),1,"") | ... BS37: =IF(AND(BS$4>=$I37,BS$4<=$J37),1,"") | BU37: Text from spec_cost_model P1-L5 desc 'KDD documentation' and slide 5 named doc 'KDDs documented / agreed'. Position is judgement: follows the workshop chain, precedes DRG close-out.
A38: G-P1-L5-s4 | B38: • DRG approval doc / DRG-ARG approval pack | C38: SEGRO | D38: ASSUMPTION | F38: G-P1-L5-s3 | G38: 4 | H38: 2 | I38: =MEDIAN($I$34,$J$34,$I$34+ROUND((G38-$G$34)/$H$34*($J$34-$I$34+1),0)) -> 4 | J38: =MEDIAN(I38,$J$34,$I$34+ROUND((G38+H38-$G$34)/$H$34*($J$34-$I$34+1),0)-1) -> 5 | K38: =IF(AND(K$4>=$I38,K$4<=$J38),1,"") | L38: =IF(AND(L$4>=$I38,L$4<=$J38),1,"") | M38: =IF(AND(M$4>=$I38,M$4<=$J38),1,"") | N38: =IF(AND(N$4>=$I38,N$4<=$J38),1,"") -> 1 | O38: =IF(AND(O$4>=$I38,O$4<=$J38),1,"") -> 1 | P38: =IF(AND(P$4>=$I38,P$4<=$J38),1,"") | Q38: =IF(AND(Q$4>=$I38,Q$4<=$J38),1,"") | R38: =IF(AND(R$4>=$I38,R$4<=$J38),1,"") | ... BS38: =IF(AND(BS$4>=$I38,BS$4<=$J38),1,"") | BU38: Slide 5 named doc 'DRG approval doc'; slide 3 lane-B item 'Arch decisions for DRG / ARG'. Position is judgement: approval pack lands at the phase tail; no drawn date for the document.
A40: G-P1-L6 | B40: Design & Plan (lane A) [P1-L6] | C40: SEGRO | D40: POAP-DRAWN | E40: F16 | G40: 1 | H40: 5 | I40: =MIN(61,IF(G40<=29,ROUND((G40-1)*(29+SlipWeeks)/29,0)+1,G40+SlipWeeks)) -> 1 | J40: =MIN(61,IF(G40+H40-1<=29,MAX(ROUND((G40+H40-1)*(29+SlipWeeks)/29,0),I40),G40+H40-1+SlipWeeks)) -> 5 | K40: =IF(AND(K$4>=$I40,K$4<=$J40),1,"") -> 1 | L40: =IF(AND(L$4>=$I40,L$4<=$J40),1,"") -> 1 | M40: =IF(AND(M$4>=$I40,M$4<=$J40),1,"") -> 1 | N40: =IF(AND(N$4>=$I40,N$4<=$J40),1,"") -> 1 | O40: =IF(AND(O$4>=$I40,O$4<=$J40),1,"") -> 1 | P40: =IF(AND(P$4>=$I40,P$4<=$J40),1,"") | Q40: =IF(AND(Q$4>=$I40,Q$4<=$J40),1,"") | R40: =IF(AND(R$4>=$I40,R$4<=$J40),1,"") | ... BS40: =IF(AND(BS$4>=$I40,BS$4<=$J40),1,"") | BT40: =IF(IF(G40+H40-1<=29,MAX(ROUND((G40+H40-1)*(29+SlipWeeks)/29,0),$I40),G40+H40-1+SlipWeeks)>61,"▶ clipped","") | BU40: Window = drawn slide 3 '5 weeks' design bar = weeks 1-5. Role/scope from spec_cost_model P1-L6: 'Project manager - mobilisation, delivery plan, procurement specification and coordination', 1 FTE.
A41: G-P1-L6-s1 | B41: • Architecture Plan & Mobilisations | C41: SEGRO | D41: DERIVED | G41: 1 | H41: 1 | I41: =MEDIAN($I$40,$J$40,$I$40+ROUND((G41-$G$40)/$H$40*($J$40-$I$40+1),0)) -> 1 | J41: =MEDIAN(I41,$J$40,$I$40+ROUND((G41+H41-$G$40)/$H$40*($J$40-$I$40+1),0)-1) -> 1 | K41: =IF(AND(K$4>=$I41,K$4<=$J41),1,"") -> 1 | L41: =IF(AND(L$4>=$I41,L$4<=$J41),1,"") | M41: =IF(AND(M$4>=$I41,M$4<=$J41),1,"") | N41: =IF(AND(N$4>=$I41,N$4<=$J41),1,"") | O41: =IF(AND(O$4>=$I41,O$4<=$J41),1,"") | P41: =IF(AND(P$4>=$I41,P$4<=$J41),1,"") | Q41: =IF(AND(Q$4>=$I41,Q$4<=$J41),1,"") | R41: =IF(AND(R$4>=$I41,R$4<=$J41),1,"") | ... BS41: =IF(AND(BS$4>=$I41,BS$4<=$J41),1,"") | BU41: Slide 3 item 'Architecture Plan & Mobilisations' (x=0.70, numbered 1) is drawn at the head of lane A - week 1 at parent start.
A42: G-P1-L6-s2 | B42: • Coordinate workshop chain and track KDD decisions | C42: SEGRO | D42: ASSUMPTION | F42: G-P1-L6-s1 | G42: 2 | H42: 3 | I42: =MEDIAN($I$40,$J$40,$I$40+ROUND((G42-$G$40)/$H$40*($J$40-$I$40+1),0)) -> 2 | J42: =MEDIAN(I42,$J$40,$I$40+ROUND((G42+H42-$G$40)/$H$40*($J$40-$I$40+1),0)-1) -> 4 | K42: =IF(AND(K$4>=$I42,K$4<=$J42),1,"") | L42: =IF(AND(L$4>=$I42,L$4<=$J42),1,"") -> 1 | M42: =IF(AND(M$4>=$I42,M$4<=$J42),1,"") -> 1 | N42: =IF(AND(N$4>=$I42,N$4<=$J42),1,"") -> 1 | O42: =IF(AND(O$4>=$I42,O$4<=$J42),1,"") | P42: =IF(AND(P$4>=$I42,P$4<=$J42),1,"") | Q42: =IF(AND(Q$4>=$I42,Q$4<=$J42),1,"") | R42: =IF(AND(R$4>=$I42,R$4<=$J42),1,"") | ... BS42: =IF(AND(BS$4>=$I42,BS$4<=$J42),1,"") | BU42: Coordination scope from spec_cost_model P1-L6 desc 'procurement specification and coordination' across the slide-3 workshop chips (drawn weeks 1-3 stagger); the coordinating activity itself has no drawn bar - position is judgement.
A43: G-P1-L6-s3 | B43: • Procurement specification (feeds the lane-B 'Procurement of desired tech stack' bar) | C43: SEGRO | D43: ASSUMPTION | F43: G-P1-L6-s2 | G43: 3 | H43: 3 | I43: =MEDIAN($I$40,$J$40,$I$40+ROUND((G43-$G$40)/$H$40*($J$40-$I$40+1),0)) -> 3 | J43: =MEDIAN(I43,$J$40,$I$40+ROUND((G43+H43-$G$40)/$H$40*($J$40-$I$40+1),0)-1) -> 5 | K43: =IF(AND(K$4>=$I43,K$4<=$J43),1,"") | L43: =IF(AND(L$4>=$I43,L$4<=$J43),1,"") | M43: =IF(AND(M$4>=$I43,M$4<=$J43),1,"") -> 1 | N43: =IF(AND(N$4>=$I43,N$4<=$J43),1,"") -> 1 | O43: =IF(AND(O$4>=$I43,O$4<=$J43),1,"") -> 1 | P43: =IF(AND(P$4>=$I43,P$4<=$J43),1,"") | Q43: =IF(AND(Q$4>=$I43,Q$4<=$J43),1,"") | R43: =IF(AND(R$4>=$I43,R$4<=$J43),1,"") | ... BS43: =IF(AND(BS$4>=$I43,BS$4<=$J43),1,"") | BU43: Slide 5 named doc 'Procurement specification'; the lane-B bar 'Procurement of desired tech stack' is drawn from x=3.10 (~week 3 of the design bar), so the spec is placed alongside it - exact position is judgement.
A44: G-P1-L6-s4 | B44: • Delivery plan | C44: SEGRO | D44: ASSUMPTION | F44: G-P1-L6-s2 | G44: 4 | H44: 2 | I44: =MEDIAN($I$40,$J$40,$I$40+ROUND((G44-$G$40)/$H$40*($J$40-$I$40+1),0)) -> 4 | J44: =MEDIAN(I44,$J$40,$I$40+ROUND((G44+H44-$G$40)/$H$40*($J$40-$I$40+1),0)-1) -> 5 | K44: =IF(AND(K$4>=$I44,K$4<=$J44),1,"") | L44: =IF(AND(L$4>=$I44,L$4<=$J44),1,"") | M44: =IF(AND(M$4>=$I44,M$4<=$J44),1,"") | N44: =IF(AND(N$4>=$I44,N$4<=$J44),1,"") -> 1 | O44: =IF(AND(O$4>=$I44,O$4<=$J44),1,"") -> 1 | P44: =IF(AND(P$4>=$I44,P$4<=$J44),1,"") | Q44: =IF(AND(Q$4>=$I44,Q$4<=$J44),1,"") | R44: =IF(AND(R$4>=$I44,R$4<=$J44),1,"") | ... BS44: =IF(AND(BS$4>=$I44,BS$4<=$J44),1,"") | BU44: Slide 5 named doc 'Delivery plan'. Position is judgement: consolidates workshop/KDD outcomes at the phase tail before 'Design phase complete'.
A46: G-P1-L7 | B46: Design & Plan (lane A) [P1-L7] | C46: HCL | D46: POAP-DRAWN | E46: F14 | G46: 1 | H46: 5 | I46: =MIN(61,IF(G46<=29,ROUND((G46-1)*(29+SlipWeeks)/29,0)+1,G46+SlipWeeks)) -> 1 | J46: =MIN(61,IF(G46+H46-1<=29,MAX(ROUND((G46+H46-1)*(29+SlipWeeks)/29,0),I46),G46+H46-1+SlipWeeks)) -> 5 | K46: =IF(AND(K$4>=$I46,K$4<=$J46),1,"") -> 1 | L46: =IF(AND(L$4>=$I46,L$4<=$J46),1,"") -> 1 | M46: =IF(AND(M$4>=$I46,M$4<=$J46),1,"") -> 1 | N46: =IF(AND(N$4>=$I46,N$4<=$J46),1,"") -> 1 | O46: =IF(AND(O$4>=$I46,O$4<=$J46),1,"") -> 1 | P46: =IF(AND(P$4>=$I46,P$4<=$J46),1,"") | Q46: =IF(AND(Q$4>=$I46,Q$4<=$J46),1,"") | R46: =IF(AND(R$4>=$I46,R$4<=$J46),1,"") | ... BS46: =IF(AND(BS$4>=$I46,BS$4<=$J46),1,"") | BT46: =IF(IF(G46+H46-1<=29,MAX(ROUND((G46+H46-1)*(29+SlipWeeks)/29,0),$I46),G46+H46-1+SlipWeeks)>61,"▶ clipped","") | BU46: Window = drawn slide 3 '5 weeks' design bar = weeks 1-5. Role/scope from spec_cost_model P1-L7: 'HCL architecture/product SME input to design workshops (UnO/TX/Unica/CDP sizing and prerequisites)', 0.6 FTE, side HCL.
...

Sheet Gantt - Revised
A1: Gantt - Corrected — technical step decomposition per major line of work
A2: The corrected sequence implementing review findings (F1/F2/F10/F16/F17/F19/F23/F26). Every window is RECOMMENDED — a proposed re-draw, not a committed plan. Cost totals are unchanged: windows move, quantities do not. The F1 re-anchor moves nominal go-live to week 31 (range weeks 29-33); the sheet renders BOTH the nominal marker and the range band, not a single committed date. Bars recalc live: SlipWeeks dilates TIME-DRIVEN windows (people + Azure commissioning) pro-rata — the same elongation the slip cost prices; FIXED-fee engagements (licences, third-party pen-test/red-team) shift but keep their duration; hypercare shifts whole. A ▶ in the Slip column flags any bar clipped at the grid edge under a large slip. Milestones: ▲ nominal go-live · ◁▷ F1 range band · ✕ Christmas · ! Bank holiday · ◆ drawn phase gate. Bar colours: SEGRO red · HCL dark blue · Azure mid blue · Third-party purple · corrected bars green (proposed, not committed).
L3: Jul 26 | O3: Aug 26 | T3: Sep 26 | X3: Oct 26 | AB3: Nov 26 | AG3: Dec 26 | AK3: Jan 27 | AO3: Feb 27 | AS3: Mar 27 | AX3: Apr 27 | BB3: May 27 | BG3: Jun 27 | BK3: Jul 27 | BO3: Aug 27 | BT3: Sep 27
A4: Id | B4: Major line of work / technical step | C4: Side | D4: Status | E4: Findings | F4: Depends on | G4: Start wk | H4: Wks | I4: Live start | J4: Live end | K4: Change vs as-drawn (per finding) | L4: 1 | M4: 2 | N4: 3 | O4: 4 | P4: 5 | Q4: 6 | R4: 7 | S4: 8 | T4: 9 | U4: 10 | V4: 11 | W4: 12 | X4: 13 | Y4: 14 | Z4: 15 | AA4: 16 | AB4: 17 | AC4: 18 | AD4: 19 | AE4: 20 | AF4: 21 | AG4: 22 | AH4: 23 | AI4: 24 | AJ4: 25 | AK4: 26 | AL4: 27 | AM4: 28 | AN4: 29 | AO4: 30 | AP4: 31 | AQ4: 32 | AR4: 33 | AS4: 34 | AT4: 35 | AU4: 36 | AV4: 37 | AW4: 38 | AX4: 39 | AY4: 40 | AZ4: 41 | BA4: 42 | BB4: 43 | BC4: 44 | BD4: 45 | BE4: 46 | BF4: 47 | BG4: 48 | BH4: 49 | BI4: 50 | BJ4: 51 | BK4: 52 | BL4: 53 | BM4: 54 | BN4: 55 | BO4: 56 | BP4: 57 | BQ4: 58 | BR4: 59 | BS4: 60 | BT4: 61 | BU4: Slip | BV4: Basis / source | BX4: =31+SlipWeeks -> 31 | BY4: =29+SlipWeeks -> 29 | BZ4: =33+SlipWeeks -> 33
B5: Go-live range (F1) | L5: =IF(L$4=$BX$4,"▲",IF(L$4=$BY$4,"◁",IF(L$4=$BZ$4,"▷",IF(AND(L$4>$BY$4,L$4<$BZ$4),"·","")))) | M5: =IF(M$4=$BX$4,"▲",IF(M$4=$BY$4,"◁",IF(M$4=$BZ$4,"▷",IF(AND(M$4>$BY$4,M$4<$BZ$4),"·","")))) | N5: =IF(N$4=$BX$4,"▲",IF(N$4=$BY$4,"◁",IF(N$4=$BZ$4,"▷",IF(AND(N$4>$BY$4,N$4<$BZ$4),"·","")))) | O5: =IF(O$4=$BX$4,"▲",IF(O$4=$BY$4,"◁",IF(O$4=$BZ$4,"▷",IF(AND(O$4>$BY$4,O$4<$BZ$4),"·","")))) | P5: =IF(P$4=$BX$4,"▲",IF(P$4=$BY$4,"◁",IF(P$4=$BZ$4,"▷",IF(AND(P$4>$BY$4,P$4<$BZ$4),"·","◆")))) -> ◆ | Q5: =IF(Q$4=$BX$4,"▲",IF(Q$4=$BY$4,"◁",IF(Q$4=$BZ$4,"▷",IF(AND(Q$4>$BY$4,Q$4<$BZ$4),"·","")))) | R5: =IF(R$4=$BX$4,"▲",IF(R$4=$BY$4,"◁",IF(R$4=$BZ$4,"▷",IF(AND(R$4>$BY$4,R$4<$BZ$4),"·","")))) | S5: =IF(S$4=$BX$4,"▲",IF(S$4=$BY$4,"◁",IF(S$4=$BZ$4,"▷",IF(AND(S$4>$BY$4,S$4<$BZ$4),"·","!")))) -> ! | T5: =IF(T$4=$BX$4,"▲",IF(T$4=$BY$4,"◁",IF(T$4=$BZ$4,"▷",IF(AND(T$4>$BY$4,T$4<$BZ$4),"·","")))) | U5: =IF(U$4=$BX$4,"▲",IF(U$4=$BY$4,"◁",IF(U$4=$BZ$4,"▷",IF(AND(U$4>$BY$4,U$4<$BZ$4),"·","")))) | V5: =IF(V$4=$BX$4,"▲",IF(V$4=$BY$4,"◁",IF(V$4=$BZ$4,"▷",IF(AND(V$4>$BY$4,V$4<$BZ$4),"·","")))) | W5: =IF(W$4=$BX$4,"▲",IF(W$4=$BY$4,"◁",IF(W$4=$BZ$4,"▷",IF(AND(W$4>$BY$4,W$4<$BZ$4),"·","")))) | X5: =IF(X$4=$BX$4,"▲",IF(X$4=$BY$4,"◁",IF(X$4=$BZ$4,"▷",IF(AND(X$4>$BY$4,X$4<$BZ$4),"·","")))) | Y5: =IF(Y$4=$BX$4,"▲",IF(Y$4=$BY$4,"◁",IF(Y$4=$BZ$4,"▷",IF(AND(Y$4>$BY$4,Y$4<$BZ$4),"·","")))) | Z5: =IF(Z$4=$BX$4,"▲",IF(Z$4=$BY$4,"◁",IF(Z$4=$BZ$4,"▷",IF(AND(Z$4>$BY$4,Z$4<$BZ$4),"·","")))) | AA5: =IF(AA$4=$BX$4,"▲",IF(AA$4=$BY$4,"◁",IF(AA$4=$BZ$4,"▷",IF(AND(AA$4>$BY$4,AA$4<$BZ$4),"·","")))) | ... AE5: =IF(AE$4=$BX$4,"▲",IF(AE$4=$BY$4,"◁",IF(AE$4=$BZ$4,"▷",IF(AND(AE$4>$BY$4,AE$4<$BZ$4),"·","")))) | AF5: =IF(AF$4=$BX$4,"▲",IF(AF$4=$BY$4,"◁",IF(AF$4=$BZ$4,"▷",IF(AND(AF$4>$BY$4,AF$4<$BZ$4),"·","◆")))) -> ◆ | AG5: =IF(AG$4=$BX$4,"▲",IF(AG$4=$BY$4,"◁",IF(AG$4=$BZ$4,"▷",IF(AND(AG$4>$BY$4,AG$4<$BZ$4),"·","")))) | AH5: =IF(AH$4=$BX$4,"▲",IF(AH$4=$BY$4,"◁",IF(AH$4=$BZ$4,"▷",IF(AND(AH$4>$BY$4,AH$4<$BZ$4),"·","")))) | AI5: =IF(AI$4=$BX$4,"▲",IF(AI$4=$BY$4,"◁",IF(AI$4=$BZ$4,"▷",IF(AND(AI$4>$BY$4,AI$4<$BZ$4),"·","✕")))) -> ✕ | AJ5: =IF(AJ$4=$BX$4,"▲",IF(AJ$4=$BY$4,"◁",IF(AJ$4=$BZ$4,"▷",IF(AND(AJ$4>$BY$4,AJ$4<$BZ$4),"·","◆")))) -> ◆ | AK5: =IF(AK$4=$BX$4,"▲",IF(AK$4=$BY$4,"◁",IF(AK$4=$BZ$4,"▷",IF(AND(AK$4>$BY$4,AK$4<$BZ$4),"·","")))) | AL5: =IF(AL$4=$BX$4,"▲",IF(AL$4=$BY$4,"◁",IF(AL$4=$BZ$4,"▷",IF(AND(AL$4>$BY$4,AL$4<$BZ$4),"·","")))) | AM5: =IF(AM$4=$BX$4,"▲",IF(AM$4=$BY$4,"◁",IF(AM$4=$BZ$4,"▷",IF(AND(AM$4>$BY$4,AM$4<$BZ$4),"·","")))) | AN5: =IF(AN$4=$BX$4,"▲",IF(AN$4=$BY$4,"◁",IF(AN$4=$BZ$4,"▷",IF(AND(AN$4>$BY$4,AN$4<$BZ$4),"·","")))) -> ◁ | AO5: =IF(AO$4=$BX$4,"▲",IF(AO$4=$BY$4,"◁",IF(AO$4=$BZ$4,"▷",IF(AND(AO$4>$BY$4,AO$4<$BZ$4),"·","")))) -> · | AP5: =IF(AP$4=$BX$4,"▲",IF(AP$4=$BY$4,"◁",IF(AP$4=$BZ$4,"▷",IF(AND(AP$4>$BY$4,AP$4<$BZ$4),"·","")))) -> ▲ | AQ5: =IF(AQ$4=$BX$4,"▲",IF(AQ$4=$BY$4,"◁",IF(AQ$4=$BZ$4,"▷",IF(AND(AQ$4>$BY$4,AQ$4<$BZ$4),"·","")))) -> · | AR5: =IF(AR$4=$BX$4,"▲",IF(AR$4=$BY$4,"◁",IF(AR$4=$BZ$4,"▷",IF(AND(AR$4>$BY$4,AR$4<$BZ$4),"·","")))) -> ▷ | ... BT5: =IF(BT$4=$BX$4,"▲",IF(BT$4=$BY$4,"◁",IF(BT$4=$BZ$4,"▷",IF(AND(BT$4>$BY$4,BT$4<$BZ$4),"·",""))))
A6: G-P2-L4-R | B6: Build - SEGRO (pulled forward into Design) [P2-L4] | C6: SEGRO | D6: RECOMMENDED | E6: F17 | G6: 3 | H6: 6 | I6: =MIN(61,IF(G6<=29,ROUND((G6-1)*(29+SlipWeeks)/29,0)+1,G6+SlipWeeks)) -> 3 | J6: =MIN(61,IF(G6+H6-1<=29,MAX(ROUND((G6+H6-1)*(29+SlipWeeks)/29,0),I6),G6+H6-1+SlipWeeks)) -> 8 | K6: Pulled forward from the full P2 span (weeks 6-15) to weeks 3-8 so security design completes before network build-out completes, not weeks after it. | L6: =IF(AND(L$4>=$I6,L$4<=$J6),1,"") | M6: =IF(AND(M$4>=$I6,M$4<=$J6),1,"") | N6: =IF(AND(N$4>=$I6,N$4<=$J6),1,"") -> 1 | O6: =IF(AND(O$4>=$I6,O$4<=$J6),1,"") -> 1 | P6: =IF(AND(P$4>=$I6,P$4<=$J6),1,"") -> 1 | Q6: =IF(AND(Q$4>=$I6,Q$4<=$J6),1,"") -> 1 | R6: =IF(AND(R$4>=$I6,R$4<=$J6),1,"") -> 1 | S6: =IF(AND(S$4>=$I6,S$4<=$J6),1,"") -> 1 | ... BT6: =IF(AND(BT$4>=$I6,BT$4<=$J6),1,"") | BU6: =IF(IF(G6+H6-1<=29,MAX(ROUND((G6+H6-1)*(29+SlipWeeks)/29,0),$I6),G6+H6-1+SlipWeeks)>61,"▶ clipped","") | BV6: F17: 'Front-load the security-design decisions that constrain network layout (segmentation model, WAF placement, private endpoints, API security) into the design phase or build weeks 1-2; keep only implementation hardening in the parallel bar' - the corrected bar starts week 3 in P1, alongside the Cyber Sec Workshop in the P1 workshop chain, and completes end of week 8 (first 3 weeks of P2), BEFORE the as-drawn network build-out (item 1, first ~half of the 10-week build) completes - avoiding rework of an already-provisioned network layout. Implementation hardening only remains in the parallel build bar per the recommendation. Quantity unchanged (25 pd likely, P2-L4).
A7: G-P2-L4-R-s1 | B7: • Security-design decisions that constrain network layout - segmentation model, WAF placement, private endpoints, API security - taken in the design phase alongside the Cyber Sec Workshop | C7: SEGRO | D7: RECOMMENDED | G7: 3 | H7: 3 | I7: =MEDIAN($I$6,$J$6,$I$6+ROUND((G7-$G$6)/$H$6*($J$6-$I$6+1),0)) -> 3 | J7: =MEDIAN(I7,$J$6,$I$6+ROUND((G7+H7-$G$6)/$H$6*($J$6-$I$6+1),0)-1) -> 5 | L7: =IF(AND(L$4>=$I7,L$4<=$J7),1,"") | M7: =IF(AND(M$4>=$I7,M$4<=$J7),1,"") | N7: =IF(AND(N$4>=$I7,N$4<=$J7),1,"") -> 1 | O7: =IF(AND(O$4>=$I7,O$4<=$J7),1,"") -> 1 | P7: =IF(AND(P$4>=$I7,P$4<=$J7),1,"") -> 1 | Q7: =IF(AND(Q$4>=$I7,Q$4<=$J7),1,"") | R7: =IF(AND(R$4>=$I7,R$4<=$J7),1,"") | S7: =IF(AND(S$4>=$I7,S$4<=$J7),1,"") | ... BT7: =IF(AND(BT$4>=$I7,BT$4<=$J7),1,"") | BV7: F17: 'Front-load the security-design decisions that constrain network layout (segmentation model, WAF placement, private endpoints, API security) into the design phase or build weeks 1-2' - taken in P1 weeks 3-5 so they are settled before any network provisioning starts in P2.
A8: G-P2-L4-R-s2 | B8: • Complete remaining cyber security design - managed identities, Key Vault, secrets management, PAM - in build weeks 1-3, before network build-out completes | C8: SEGRO | D8: RECOMMENDED | F8: G-P2-L4-R-s1 | G8: 6 | H8: 3 | I8: =MEDIAN($I$6,$J$6,$I$6+ROUND((G8-$G$6)/$H$6*($J$6-$I$6+1),0)) -> 6 | J8: =MEDIAN(I8,$J$6,$I$6+ROUND((G8+H8-$G$6)/$H$6*($J$6-$I$6+1),0)-1) -> 8 | L8: =IF(AND(L$4>=$I8,L$4<=$J8),1,"") | M8: =IF(AND(M$4>=$I8,M$4<=$J8),1,"") | N8: =IF(AND(N$4>=$I8,N$4<=$J8),1,"") | O8: =IF(AND(O$4>=$I8,O$4<=$J8),1,"") | P8: =IF(AND(P$4>=$I8,P$4<=$J8),1,"") | Q8: =IF(AND(Q$4>=$I8,Q$4<=$J8),1,"") -> 1 | R8: =IF(AND(R$4>=$I8,R$4<=$J8),1,"") -> 1 | S8: =IF(AND(S$4>=$I8,S$4<=$J8),1,"") -> 1 | ... BT8: =IF(AND(BT$4>=$I8,BT$4<=$J8),1,"") | BV8: F17: 'keep only implementation hardening in the parallel bar' - the design content completes by week 8, ahead of the network build-out finishing; only implementation hardening continues alongside the rest of the build.
A10: G-P1-REV-R | B10: Design & Plan | C10: SEGRO | D10: RECOMMENDED | E10: F16 | G10: 2 | H10: 6 | I10: =MIN(61,IF(G10<=29,ROUND((G10-1)*(29+SlipWeeks)/29,0)+1,G10+SlipWeeks)) -> 2 | J10: =MIN(61,IF(G10+H10-1<=29,MAX(ROUND((G10+H10-1)*(29+SlipWeeks)/29,0),I10),G10+H10-1+SlipWeeks)) -> 7 | K10: New TAD/HLD/LLD review-and-revision track inside P1 extending 2 weeks into early P2; no as-drawn counterpart exists - the as-drawn plan has no review or revision cycle at all. | L10: =IF(AND(L$4>=$I10,L$4<=$J10),1,"") | M10: =IF(AND(M$4>=$I10,M$4<=$J10),1,"") -> 1 | N10: =IF(AND(N$4>=$I10,N$4<=$J10),1,"") -> 1 | O10: =IF(AND(O$4>=$I10,O$4<=$J10),1,"") -> 1 | P10: =IF(AND(P$4>=$I10,P$4<=$J10),1,"") -> 1 | Q10: =IF(AND(Q$4>=$I10,Q$4<=$J10),1,"") -> 1 | R10: =IF(AND(R$4>=$I10,R$4<=$J10),1,"") -> 1 | S10: =IF(AND(S$4>=$I10,S$4<=$J10),1,"") | ... BT10: =IF(AND(BT$4>=$I10,BT$4<=$J10),1,"") | BU10: =IF(IF(G10+H10-1<=29,MAX(ROUND((G10+H10-1)*(29+SlipWeeks)/29,0),$I10),G10+H10-1+SlipWeeks)>61,"▶ clipped","") | BV10: F16: 'Publish a review/approval schedule per gating document (owner, turnaround SLA, revision allowance) and hold at least one built-in revision cycle before the build-start gate' - NEW explicit TAD/HLD/LLD review + revision track covering the 14 slide-5 design documents. One full revision loop for 14 documents does not fit inside the 5-week P1 window on top of authoring, so the track runs weeks 2-7, extending 2 weeks into early P2. Build-start impact, stated honestly: SEGRO build tasks gated on an approved TAD/HLD/LLD/DRG pack carry up to a 2-week start risk against the week-6 build start; this risk is absorbed in the go-live range shown in G-TEST-REANCHOR-R. No cost change - review effort sits inside the existing P1 role lines (P1-L1 to P1-L7), which is why no single cost_line is cited.
A11: G-P1-REV-R-s1 | B11: • Publish the review/approval schedule per gating document - owner, turnaround SLA, revision allowance - for all 14 slide-5 design documents (TAD, HLD, LLD, DRG pack and the rest) | C11: SEGRO | D11: RECOMMENDED | G11: 2 | H11: 1 | I11: =MEDIAN($I$10,$J$10,$I$10+ROUND((G11-$G$10)/$H$10*($J$10-$I$10+1),0)) -> 2 | J11: =MEDIAN(I11,$J$10,$I$10+ROUND((G11+H11-$G$10)/$H$10*($J$10-$I$10+1),0)-1) -> 2 | L11: =IF(AND(L$4>=$I11,L$4<=$J11),1,"") | M11: =IF(AND(M$4>=$I11,M$4<=$J11),1,"") -> 1 | N11: =IF(AND(N$4>=$I11,N$4<=$J11),1,"") | O11: =IF(AND(O$4>=$I11,O$4<=$J11),1,"") | P11: =IF(AND(P$4>=$I11,P$4<=$J11),1,"") | Q11: =IF(AND(Q$4>=$I11,Q$4<=$J11),1,"") | R11: =IF(AND(R$4>=$I11,R$4<=$J11),1,"") | S11: =IF(AND(S$4>=$I11,S$4<=$J11),1,"") | ... BT11: =IF(AND(BT$4>=$I11,BT$4<=$J11),1,"") | BV11: F16: 'Publish a review/approval schedule per gating document (owner, turnaround SLA, revision allowance)' - schedule issued in week 2 so reviews can start as documents land.
A12: G-P1-REV-R-s2 | B12: • First-pass reviews of the 14 slide-5 design documents as they land through the P1 workshop chain | C12: SEGRO | D12: RECOMMENDED | F12: G-P1-REV-R-s1 | G12: 3 | H12: 3 | I12: =MEDIAN($I$10,$J$10,$I$10+ROUND((G12-$G$10)/$H$10*($J$10-$I$10+1),0)) -> 3 | J12: =MEDIAN(I12,$J$10,$I$10+ROUND((G12+H12-$G$10)/$H$10*($J$10-$I$10+1),0)-1) -> 5 | L12: =IF(AND(L$4>=$I12,L$4<=$J12),1,"") | M12: =IF(AND(M$4>=$I12,M$4<=$J12),1,"") | N12: =IF(AND(N$4>=$I12,N$4<=$J12),1,"") -> 1 | O12: =IF(AND(O$4>=$I12,O$4<=$J12),1,"") -> 1 | P12: =IF(AND(P$4>=$I12,P$4<=$J12),1,"") -> 1 | Q12: =IF(AND(Q$4>=$I12,Q$4<=$J12),1,"") | R12: =IF(AND(R$4>=$I12,R$4<=$J12),1,"") | S12: =IF(AND(S$4>=$I12,S$4<=$J12),1,"") | ... BT12: =IF(AND(BT$4>=$I12,BT$4<=$J12),1,"") | BV12: F16: reviews executed against the published schedule's 'turnaround SLA' during weeks 3-5, while the documents are being authored - not deferred past 'Design phase complete'.
A13: G-P1-REV-R-s3 | B13: • Built-in revision cycle: revise, re-review and approve the gating documents (TAD, HLD, LLD, DRG approval) before the build-start gate | C13: SEGRO | D13: RECOMMENDED | F13: G-P1-REV-R-s2 | G13: 6 | H13: 2 | I13: =MEDIAN($I$10,$J$10,$I$10+ROUND((G13-$G$10)/$H$10*($J$10-$I$10+1),0)) -> 6 | J13: =MEDIAN(I13,$J$10,$I$10+ROUND((G13+H13-$G$10)/$H$10*($J$10-$I$10+1),0)-1) -> 7 | L13: =IF(AND(L$4>=$I13,L$4<=$J13),1,"") | M13: =IF(AND(M$4>=$I13,M$4<=$J13),1,"") | N13: =IF(AND(N$4>=$I13,N$4<=$J13),1,"") | O13: =IF(AND(O$4>=$I13,O$4<=$J13),1,"") | P13: =IF(AND(P$4>=$I13,P$4<=$J13),1,"") | Q13: =IF(AND(Q$4>=$I13,Q$4<=$J13),1,"") -> 1 | R13: =IF(AND(R$4>=$I13,R$4<=$J13),1,"") -> 1 | S13: =IF(AND(S$4>=$I13,S$4<=$J13),1,"") | ... BT13: =IF(AND(BT$4>=$I13,BT$4<=$J13),1,"") | BV13: F16: 'hold at least one built-in revision cycle before the build-start gate' - the revision loop runs weeks 6-7 (early P2); build tasks gated on approved designs carry up to a 2-week start risk, noted in the parent basis.
